Workbook

Sheet Validation - Code Output
A1: Table 1
A2: Rank | B2: Team | C2: Rating - Code Output | D2: Rating - Manual in Excel
A3: 1 | B3: Notre Dame | C3: 7.7537153 | D3: {=VLOOKUP($B3,'Matrix Output'!$A1:$EJ137,140,FALSE)} -> 7.7537153
A4: 2 | B4: Florida | C4: 6.8918867 | D4: {=VLOOKUP($B4,'Matrix Output'!$A1:$EJ137,140,FALSE)} -> 6.8918867
A5: 3 | B5: Oregon | C5: 6.8199132 | D5: {=VLOOKUP($B5,'Matrix Output'!$A1:$EJ137,140,FALSE)} -> 6.8199132
A6: 4 | B6: USC | C6: 6.1075652 | D6: {=VLOOKUP($B6,'Matrix Output'!$A1:$EJ137,140,FALSE)} -> 6.1075652
A7: 5 | B7: SMU | C7: 6.0318777 | D7: {=VLOOKUP($B7,'Matrix Output'!$A1:$EJ137,140,FALSE)} -> 6.0318777
A8: 6 | B8: Texas | C8: 5.9882203 | D8: {=VLOOKUP($B8,'Matrix Output'!$A1:$EJ137,140,FALSE)} -> 5.9882203
A9: 7 | B9: Oklahoma | C9: 5.6719954 | D9: {=VLOOKUP($B9,'Matrix Output'!$A1:$EJ137,140,FALSE)} -> 5.6719954
A10: 8 | B10: Texas Tech | C10: 5.5998277 | D10: {=VLOOKUP($B10,'Matrix Output'!$A1:$EJ137,140,FALSE)} -> 5.5998277
A11: 9 | B11: Georgia | C11: 5.591297 | D11: {=VLOOKUP($B11,'Matrix Output'!$A1:$EJ137,140,FALSE)} -> 5.591297
A12: 10 | B12: Mississippi | C12: 5.5136048 | D12: {=VLOOKUP($B12,'Matrix Output'!$A1:$EJ137,140,FALSE)} -> 5.5136048
A13: 11 | B13: Utah | C13: 5.4656876 | D13: {=VLOOKUP($B13,'Matrix Output'!$A1:$EJ137,140,FALSE)} -> 5.4656876
A14: 12 | B14: Ohio St | C14: 5.2748384 | D14: {=VLOOKUP($B14,'Matrix Output'!$A1:$EJ137,140,FALSE)} -> 5.2748384
A15: 13 | B15: Alabama | C15: 5.2283042 | D15: {=VLOOKUP($B15,'Matrix Output'!$A1:$EJ137,140,FALSE)} -> 5.2283042
A16: 14 | B16: Miami | C16: 5.0922019 | D16: {=VLOOKUP($B16,'Matrix Output'!$A1:$EJ137,140,FALSE)} -> 5.0922019
A17: 15 | B17: Illinois | C17: 4.5934518 | D17: {=VLOOKUP($B17,'Matrix Output'!$A1:$EJ137,140,FALSE)} -> 4.5934518
A18: 16 | B18: Kansas | C18: 4.578754 | D18: {=VLOOKUP($B18,'Matrix Output'!$A1:$EJ137,140,FALSE)} -> 4.578754
A19: 17 | B19: Tulane | C19: 4.5591367 | D19: {=VLOOKUP($B19,'Matrix Output'!$A1:$EJ137,140,FALSE)} -> 4.5591367
A20: 18 | B20: Toledo | C20: 4.558876 | D20: {=VLOOKUP($B20,'Matrix Output'!$A1:$EJ137,140,FALSE)} -> 4.558876
A21: 19 | B21: Iowa St | C21: 4.401892 | D21: {=VLOOKUP($B21,'Matrix Output'!$A1:$EJ137,140,FALSE)} -> 4.401892
A22: 20 | B22: Louisville | C22: 4.3112326 | D22: {=VLOOKUP($B22,'Matrix Output'!$A1:$EJ137,140,FALSE)} -> 4.3112326
A23: 21 | B23: Texas A&M | C23: 4.2657068 | D23: {=VLOOKUP($B23,'Matrix Output'!$A1:$EJ137,140,FALSE)} -> 4.2657068
A24: 22 | B24: Missouri | C24: 4.0142572 | D24: {=VLOOKUP($B24,'Matrix Output'!$A1:$EJ137,140,FALSE)} -> 4.0142572
A25: 23 | B25: Georgia Tech | C25: 4.0043546 | D25: {=VLOOKUP($B25,'Matrix Output'!$A1:$EJ137,140,FALSE)} -> 4.0043546
A26: 24 | B26: Michigan | C26: 3.9426785 | D26: {=VLOOKUP($B26,'Matrix Output'!$A1:$EJ137,140,FALSE)} -> 3.9426785
A27: 25 | B27: Tennessee | C27: 3.9035829 | D27: {=VLOOKUP($B27,'Matrix Output'!$A1:$EJ137,140,FALSE)} -> 3.9035829
A28: 26 | B28: Vanderbilt | C28: 3.6994365 | D28: {=VLOOKUP($B28,'Matrix Output'!$A1:$EJ137,140,FALSE)} -> 3.6994365
A29: 27 | B29: LSU | C29: 3.6549276 | D29: {=VLOOKUP($B29,'Matrix Output'!$A1:$EJ137,140,FALSE)} -> 3.6549276
A30: 28 | B30: Florida St | C30: 3.5726018 | D30: {=VLOOKUP($B30,'Matrix Output'!$A1:$EJ137,140,FALSE)} -> 3.5726018
A31: 29 | B31: TCU | C31: 3.4749183 | D31: {=VLOOKUP($B31,'Matrix Output'!$A1:$EJ137,140,FALSE)} -> 3.4749183
A32: 30 | B32: Mississippi St | C32: 3.4608221 | D32: {=VLOOKUP($B32,'Matrix Output'!$A1:$EJ137,140,FALSE)} -> 3.4608221
A33: 31 | B33: West Virginia | C33: 3.3151201 | D33: {=VLOOKUP($B33,'Matrix Output'!$A1:$EJ137,140,FALSE)} -> 3.3151201
A34: 32 | B34: N Texas | C34: 3.2610572 | D34: {=VLOOKUP($B34,'Matrix Output'!$A1:$EJ137,140,FALSE)} -> 3.2610572
A35: 33 | B35: Navy | C35: 3.2433579 | D35: {=VLOOKUP($B35,'Matrix Output'!$A1:$EJ137,140,FALSE)} -> 3.2433579
A36: 34 | B36: Duke | C36: 3.1946532 | D36: {=VLOOKUP($B36,'Matrix Output'!$A1:$EJ137,140,FALSE)} -> 3.1946532
A37: 35 | B37: Penn St | C37: 3.1020273 | D37: {=VLOOKUP($B37,'Matrix Output'!$A1:$EJ137,140,FALSE)} -> 3.1020273
A38: 36 | B38: Virginia | C38: 2.8154897 | D38: {=VLOOKUP($B38,'Matrix Output'!$A1:$EJ137,140,FALSE)} -> 2.8154897
A39: 37 | B39: Iowa | C39: 2.7790891 | D39: {=VLOOKUP($B39,'Matrix Output'!$A1:$EJ137,140,FALSE)} -> 2.7790891
A40: 38 | B40: South Carolina | C40: 2.7432077 | D40: {=VLOOKUP($B40,'Matrix Output'!$A1:$EJ137,140,FALSE)} -> 2.7432077
...

Sheet Matrix Output
B1: Air Force | C1: Akron | D1: Alabama | E1: App State | F1: Arizona St | G1: Arizona | H1: Arkansas St | I1: Arkansas | J1: Army | K1: Auburn | L1: BYU | M1: Ball St | N1: Baylor | O1: Boise St | P1: Boston College | Q1: Bowling Green | R1: Buffalo | S1: C Michigan | T1: California | U1: Charlotte | V1: Cincinnati | W1: Clemson | X1: Coastal Car | Y1: Colorado St | Z1: Colorado | AA1: Delaware | AB1: Duke | AC1: E Carolina | AD1: E Michigan | AE1: Florida Atlantic | AF1: Florida Intl | AG1: Florida St | AH1: Florida | AI1: Fresno St | AJ1: Georgia So | AK1: Georgia St | AL1: Georgia Tech | AM1: Georgia | AN1: Hawai'i | AO1: Houston | AP1: Illinois | AQ1: Indiana | AR1: Iowa St | AS1: Iowa | AT1: J Madison | AU1: Jacksonville St | AV1: Kansas St | AW1: Kansas | AX1: Kennesaw St | AY1: Kent St | AZ1: Kentucky | BA1: LSU | BB1: Liberty | BC1: Louisiana Tech | BD1: Louisiana | BE1: Louisville | BF1: Marshall | BG1: Maryland | BH1: Memphis | BI1: Miami OH | BJ1: Miami | BK1: Michigan St | BL1: Michigan | BM1: Middle Tenn | BN1: Minnesota | BO1: Mississippi St | BP1: Mississippi | BQ1: Missouri St | BR1: Missouri | BS1: N Illinois | BT1: N Texas | BU1: NC State | BV1: Navy | BW1: Nebraska | BX1: Nevada | BY1: New Mexico St | BZ1: New Mexico | CA1: North Carolina | CB1: Northwestern | CC1: Notre Dame | CD1: Ohio St | CE1: Ohio | CF1: Oklahoma St | CG1: Oklahoma | CH1: Old Dominion | CI1: Oregon St | CJ1: Oregon | CK1: Penn St | CL1: Pittsburgh | CM1: Purdue | CN1: Rice | CO1: Rutgers | CP1: S Alabama | CQ1: S Florida | CR1: SMU | CS1: Sam Houston | CT1: San Diego St | CU1: San Jose St | CV1: South Carolina | CW1: Southern Miss | CX1: Stanford | CY1: Syracuse | CZ1: TCU | DA1: Temple | DB1: Tennessee | DC1: Texas A&M | DD1: Texas St | DE1: Texas Tech | DF1: Texas | DG1: Toledo | DH1: Troy | DI1: Tulane | DJ1: Tulsa | DK1: UAB | DL1: UCF | DM1: UCLA | DN1: UConn | DO1: UL Monroe | DP1: UMass | DQ1: UNLV | DR1: USC | DS1: UTEP | DT1: UTSA | DU1: Utah St | DV1: Utah | DW1: Vanderbilt | DX1: Virginia Tech | DY1: Virginia | DZ1: W Kentucky | EA1: W Michigan | EB1: Wake Forest | EC1: Washington St | ED1: Washington | EE1: West Virginia | EF1: Wisconsin | EG1: Wyoming | EH1: Adjusted Win Total | EI1: Avg Opponent Rating | EJ1: Final Rating
A2: Air Force | B2: 0 | C2: 0 | D2: 0 | E2: 0 | F2: 0 | G2: 0 | H2: 0 | I2: 0 | J2: 0 | K2: 0 | L2: 0 | M2: 0.875 | N2: 0 | O2: 0 | P2: 0 | Q2: 0 | R2: 0 | S2: 0 | T2: 0 | U2: 0 | V2: 0 | W2: 0 | X2: 0 | Y2: 0 | Z2: 0 | AA2: 0 | AB2: 0 | AC2: 0 | AD2: 0 | AE2: 0 | AF2: 0 | AG2: 0 | AH2: 0 | AI2: 0 | AJ2: 0 | AK2: 0 | AL2: 0 | AM2: 0 | AN2: 0 | AO2: 0 | AP2: 0 | AQ2: 0 | AR2: 0 | AS2: 0 | AT2: 0 | AU2: 0 | AV2: 0 | AW2: 0 | AX2: 0 | AY2: 0 | AZ2: 0 | BA2: 0 | BB2: 0 | BC2: 0 | BD2: 1.125 | BE2: 0 | BF2: 0 | BG2: 0 | BH2: 0 | BI2: 0 | BJ2: 0 | BK2: 0 | BL2: 0 | BM2: 0 | BN2: 0 | BO2: 0 | BP2: 0 | BQ2: 0 | BR2: 0 | BS2: 0 | BT2: 0 | BU2: 0 | BV2: 0 | BW2: 0 | BX2: 0 | BY2: 0 | BZ2: 0 | CA2: 0 | CB2: -0.875 | CC2: -0.875 | CD2: 0 | CE2: 0 | CF2: 0 | CG2: 0 | CH2: 0 | CI2: 1.125 | CJ2: 0 | CK2: 0 | CL2: 0 | CM2: 0 | CN2: 0 | CO2: 0 | CP2: 0 | CQ2: 0 | CR2: 0 | CS2: 0 | CT2: 0 | CU2: 0 | CV2: 0 | CW2: 0 | CX2: 0 | CY2: 0 | CZ2: -1.125 | DA2: 0 | DB2: 0 | DC2: 0 | DD2: -0.875 | DE2: 0 | DF2: 0 | DG2: 0 | DH2: 0 | DI2: 0 | DJ2: 0 | DK2: 0 | DL2: 0 | DM2: 0 | DN2: 0 | DO2: 0 | DP2: 0 | DQ2: 0 | DR2: 0 | DS2: 0 | DT2: 0 | DU2: 0 | DV2: 0 | DW2: 0 | DX2: 0 | DY2: 0 | DZ2: 0 | EA2: 0 | EB2: 0 | EC2: 0 | ED2: 0 | EE2: 0 | EF2: 0 | EG2: 0 | EH2: -0.625 | EI2: {=VLOOKUP(A2,'Opponent List'!$A1:$P137,16,FALSE)} -> -0.54460187 | EJ2: -1.1696052
A3: Akron | B3: 0 | C3: 0 | D3: 0 | E3: 0 | F3: 0 | G3: 0 | H3: 0 | I3: 0 | J3: 0 | K3: 0 | L3: 0 | M3: 0 | N3: 0 | O3: 0 | P3: 0 | Q3: 0 | R3: 0 | S3: 0 | T3: 0 | U3: 0 | V3: 0 | W3: 0 | X3: 0 | Y3: 0 | Z3: 0 | AA3: 0 | AB3: 0 | AC3: 0 | AD3: 0 | AE3: 0 | AF3: 0 | AG3: 0 | AH3: 0 | AI3: 0 | AJ3: 0 | AK3: 0 | AL3: 0 | AM3: 0 | AN3: 0 | AO3: 0 | AP3: 0 | AQ3: 0 | AR3: 0 | AS3: -1.125 | AT3: 0 | AU3: 0 | AV3: 0 | AW3: 0 | AX3: 0 | AY3: 0 | AZ3: 0 | BA3: 0 | BB3: 0 | BC3: 0 | BD3: 0 | BE3: 0 | BF3: 0 | BG3: 0 | BH3: 0 | BI3: 0.875 | BJ3: 0 | BK3: 0 | BL3: 0 | BM3: 0 | BN3: 0 | BO3: 0 | BP3: 0 | BQ3: 0 | BR3: 0 | BS3: 0 | BT3: 0 | BU3: 0 | BV3: 0 | BW3: 0 | BX3: 0 | BY3: 0 | BZ3: 0 | CA3: 0 | CB3: 0 | CC3: 0 | CD3: 0 | CE3: -1.125 | CF3: 0 | CG3: 0 | CH3: 0 | CI3: 0 | CJ3: 0 | CK3: 0 | CL3: 0 | CM3: 0 | CN3: 0 | CO3: 0 | CP3: 0 | CQ3: 0 | CR3: 0 | CS3: 0 | CT3: 0 | CU3: 0 | CV3: 0 | CW3: 0 | CX3: 0 | CY3: 0 | CZ3: 0 | DA3: 0 | DB3: 0 | DC3: -1.125 | DD3: 0 | DE3: 0 | DF3: 0 | DG3: 0 | DH3: 0 | DI3: 0 | DJ3: 0 | DK3: 0 | DL3: 0 | DM3: 0 | DN3: 0 | DO3: 0 | DP3: 0 | DQ3: 0 | DR3: 0 | DS3: -1.125 | DT3: 0 | DU3: 0 | DV3: 0 | DW3: 0 | DX3: 0 | DY3: 0 | DZ3: 0 | EA3: 0 | EB3: 0 | EC3: -0.875 | ED3: 0 | EE3: 0 | EF3: 0 | EG3: -0.875 | EH3: -5.375 | EI3: {=VLOOKUP(A3,'Opponent List'!$A1:$P137,16,FALSE)} -> -0.57090071 | EJ3: -5.9460984
A4: Alabama | B4: 0 | C4: 0 | D4: 0 | E4: 0 | F4: 0 | G4: 0 | H4: 0 | I4: 0 | J4: 0 | K4: 0 | L4: 0 | M4: 0.875 | N4: 0 | O4: 0 | P4: 0 | Q4: 0 | R4: 0 | S4: 0 | T4: 0 | U4: 0 | V4: 0 | W4: 0 | X4: 0 | Y4: 0 | Z4: 0 | AA4: 0 | AB4: 0 | AC4: 0 | AD4: 0 | AE4: 0 | AF4: 0 | AG4: 0 | AH4: 0 | AI4: 0 | AJ4: 0 | AK4: 0 | AL4: 0 | AM4: 0 | AN4: 0 | AO4: 0 | AP4: 0 | AQ4: 0 | AR4: 0 | AS4: 0 | AT4: 0.875 | AU4: 0 | AV4: 0 | AW4: 0 | AX4: 0 | AY4: 0 | AZ4: 0 | BA4: 0 | BB4: 0 | BC4: 1.125 | BD4: 0 | BE4: 0.875 | BF4: 0 | BG4: 0 | BH4: 0 | BI4: 0 | BJ4: 0 | BK4: 0 | BL4: 0 | BM4: 0 | BN4: 0 | BO4: 0 | BP4: 0 | BQ4: 0 | BR4: 0 | BS4: 0 | BT4: 0 | BU4: 0 | BV4: 0 | BW4: 0 | BX4: 0 | BY4: 0 | BZ4: 0 | CA4: 0 | CB4: 0 | CC4: 0 | CD4: 0 | CE4: 0 | CF4: 0 | CG4: 0 | CH4: 0.875 | CI4: 0 | CJ4: -0.875 | CK4: 0 | CL4: 0 | CM4: 0 | CN4: 0 | CO4: 0 | CP4: 0 | CQ4: 0 | CR4: 0 | CS4: 0 | CT4: 0 | CU4: 0 | CV4: 0 | CW4: 0 | CX4: 0 | CY4: 0 | CZ4: 0 | DA4: 0 | DB4: 0 | DC4: 0 | DD4: 0 | DE4: 0 | DF4: 0 | DG4: 0 | DH4: 0 | DI4: 0 | DJ4: 0 | DK4: 0 | DL4: 0 | DM4: 0 | DN4: 0 | DO4: 0 | DP4: 0 | DQ4: 0 | DR4: 0 | DS4: 0 | DT4: 0 | DU4: 0 | DV4: 0.875 | DW4: 0 | DX4: 0 | DY4: 0 | DZ4: 0 | EA4: 0 | EB4: 0 | EC4: 0 | ED4: 0 | EE4: 0 | EF4: 0 | EG4: 0 | EH4: 4.625 | EI4: {=VLOOKUP(A4,'Opponent List'!$A1:$P137,16,FALSE)} -> 0.60355346 | EJ4: 5.2283042
A5: App State | B5: 0 | C5: 0 | D5: 0 | E5: 0 | F5: 0 | G5: 0 | H5: 0 | I5: 0 | J5: 0 | K5: 0 | L5: 0 | M5: 0 | N5: -1.125 | O5: 0 | P5: 0 | Q5: 0 | R5: 0 | S5: 0 | T5: 0 | U5: 0 | V5: 0 | W5: 0 | X5: 0 | Y5: 0 | Z5: 0 | AA5: 0 | AB5: 1.125 | AC5: 0 | AD5: 0 | AE5: 0 | AF5: -1.125 | AG5: 0 | AH5: 0 | AI5: 0 | AJ5: 0 | AK5: 0 | AL5: 0 | AM5: 0 | AN5: 0 | AO5: 0 | AP5: 0 | AQ5: 0 | AR5: 0 | AS5: 0 | AT5: 0 | AU5: 0 | AV5: 0 | AW5: 0 | AX5: 0 | AY5: 0 | AZ5: -0.875 | BA5: 0 | BB5: 0 | BC5: -0.875 | BD5: 0 | BE5: 0 | BF5: 0 | BG5: 0 | BH5: 0 | BI5: 0 | BJ5: 0 | BK5: 0 | BL5: 0 | BM5: 0 | BN5: 0 | BO5: 0 | BP5: 0 | BQ5: 0 | BR5: 0 | BS5: 0 | BT5: 0 | BU5: 0 | BV5: 0 | BW5: 0 | BX5: 0 | BY5: 0 | BZ5: -0.875 | CA5: 0 | CB5: 0 | CC5: 0 | CD5: 0 | CE5: 0 | CF5: 0 | CG5: 0 | CH5: 0 | CI5: 0 | CJ5: 0 | CK5: 0 | CL5: 0 | CM5: 0 | CN5: 0 | CO5: 0 | CP5: 0 | CQ5: 0 | CR5: 0 | CS5: 0 | CT5: 0 | CU5: 0 | CV5: 0 | CW5: 0 | CX5: 0 | CY5: 0 | CZ5: 0 | DA5: 0 | DB5: 0 | DC5: 0 | DD5: 0 | DE5: 0 | DF5: 0 | DG5: 0 | DH5: 0 | DI5: 0 | DJ5: 0 | DK5: 0 | DL5: 0 | DM5: 0 | DN5: 0 | DO5: 0 | DP5: 0 | DQ5: 0 | DR5: 0 | DS5: 0 | DT5: 0 | DU5: 0 | DV5: 0 | DW5: -0.875 | DX5: 0 | DY5: 0 | DZ5: 0 | EA5: 0 | EB5: 0 | EC5: 0 | ED5: 0 | EE5: 0 | EF5: 0 | EG5: 0 | EH5: -4.625 | EI5: {=VLOOKUP(A5,'Opponent List'!$A1:$P137,16,FALSE)} -> 0.50981926 | EJ5: -4.1152425
A6: Arizona St | B6: 0 | C6: 0 | D6: 0 | E6: 0 | F6: 0 | G6: 0 | H6: 0 | I6: 0 | J6: 0 | K6: 0 | L6: 0 | M6: 0 | N6: 1.125 | O6: 0 | P6: 0 | Q6: 0 | R6: 0 | S6: 0 | T6: 0 | U6: 0 | V6: 0 | W6: 0 | X6: 0 | Y6: 0 | Z6: 0 | AA6: 0 | AB6: 0 | AC6: 0 | AD6: 0 | AE6: 0 | AF6: 0 | AG6: 0 | AH6: 0 | AI6: 0 | AJ6: 0 | AK6: 0 | AL6: 0 | AM6: -1.125 | AN6: 0 | AO6: 0 | AP6: 0 | AQ6: 0 | AR6: 0 | AS6: 0 | AT6: 0 | AU6: 0 | AV6: 0 | AW6: 0 | AX6: 0 | AY6: 0 | AZ6: 0 | BA6: 0 | BB6: 0 | BC6: 0 | BD6: 0 | BE6: 0 | BF6: 0 | BG6: 0 | BH6: 0 | BI6: 0 | BJ6: 0 | BK6: 0 | BL6: 0 | BM6: 0 | BN6: 0 | BO6: 0 | BP6: -1.125 | BQ6: 0 | BR6: 0 | BS6: 0 | BT6: 0 | BU6: 0 | BV6: 0 | BW6: 0 | BX6: 0 | BY6: 0 | BZ6: 0 | CA6: 0 | CB6: 0 | CC6: 0 | CD6: 0 | CE6: 0 | CF6: 0 | CG6: 0 | CH6: -0.875 | CI6: 0 | CJ6: 0 | CK6: 0 | CL6: 0 | CM6: 0 | CN6: 0 | CO6: 0 | CP6: 0 | CQ6: 0 | CR6: 0 | CS6: 0 | CT6: 0 | CU6: 0 | CV6: 0 | CW6: 0 | CX6: 1.125 | CY6: 1.125 | CZ6: 0 | DA6: 0 | DB6: 0.875 | DC6: 0 | DD6: 0 | DE6: 0 | DF6: 0 | DG6: 0 | DH6: 0 | DI6: 0 | DJ6: 0 | DK6: 0 | DL6: 0 | DM6: 0 | DN6: 0 | DO6: 0 | DP6: 0 | DQ6: 0 | DR6: 0 | DS6: 0 | DT6: 0 | DU6: 0 | DV6: 0 | DW6: 0 | DX6: 0 | DY6: 0 | DZ6: 0 | EA6: 0 | EB6: 0 | EC6: 0 | ED6: 0 | EE6: 0 | EF6: 0 | EG6: 0 | EH6: 1.125 | EI6: {=VLOOKUP(A6,'Opponent List'!$A1:$P137,16,FALSE)} -> 1.1198859 | EJ6: 2.2448529
A7: Arizona | B7: 0 | C7: 0 | D7: 0 | E7: 0 | F7: 0 | G7: 0 | H7: 0 | I7: 0 | J7: 0 | K7: 0 | L7: 0 | M7: 0 | N7: 0 | O7: 0 | P7: 0 | Q7: 0 | R7: 0 | S7: 0 | T7: 0 | U7: 0 | V7: 0 | W7: 0 | X7: 0 | Y7: 0 | Z7: 0 | AA7: 0 | AB7: 0 | AC7: 0 | AD7: 0 | AE7: 0 | AF7: 0 | AG7: 0 | AH7: 0 | AI7: 0 | AJ7: 0 | AK7: 0 | AL7: -0.875 | AM7: 0 | AN7: 0.875 | AO7: 0 | AP7: 0 | AQ7: 0 | AR7: 0 | AS7: 0 | AT7: 0 | AU7: 0 | AV7: 0 | AW7: 0 | AX7: 0 | AY7: 0 | AZ7: 0 | BA7: 0 | BB7: 0 | BC7: 0 | BD7: 0 | BE7: 0 | BF7: 0 | BG7: 0 | BH7: 0 | BI7: 0 | BJ7: 0 | BK7: 0 | BL7: 0 | BM7: 0 | BN7: 0 | BO7: 0 | BP7: 0 | BQ7: 0 | BR7: 0 | BS7: 0 | BT7: 0 | BU7: 0 | BV7: 0 | BW7: 0 | BX7: 0 | BY7: 1.125 | BZ7: 0 | CA7: 0 | CB7: 0 | CC7: -0.875 | CD7: 0 | CE7: 0 | CF7: 0 | CG7: 0 | CH7: 0 | CI7: 0 | CJ7: 0 | CK7: 0 | CL7: -0.875 | CM7: 0 | CN7: 0 | CO7: 0 | CP7: 0 | CQ7: 0 | CR7: 0 | CS7: 0 | CT7: 0 | CU7: 0 | CV7: 0 | CW7: 0 | CX7: 0 | CY7: 0 | CZ7: 0 | DA7: 0 | DB7: 0 | DC7: 0 | DD7: 0 | DE7: 0 | DF7: 0 | DG7: -0.875 | DH7: 0 | DI7: 0 | DJ7: 0 | DK7: 0 | DL7: 0 | DM7: 0 | DN7: 0 | DO7: 0 | DP7: 0 | DQ7: 0 | DR7: 0 | DS7: 0 | DT7: 0 | DU7: 0 | DV7: 0 | DW7: 0.875 | DX7: 0 | DY7: 0 | DZ7: 0 | EA7: 0 | EB7: 0 | EC7: 0 | ED7: 0 | EE7: 0 | EF7: 0 | EG7: 0 | EH7: -0.625 | EI7: {=VLOOKUP(A7,'Opponent List'!$A1:$P137,16,FALSE)} -> 2.5137127 | EJ7: 1.8886351
A8: Arkansas St | B8: 0 | C8: 0 | D8: 0 | E8: 0 | F8: 0 | G8: 0 | H8: 0 | I8: 0 | J8: 0 | K8: 0 | L8: -0.875 | M8: 0 | N8: 0 | O8: 0 | P8: 0 | Q8: 0 | R8: 0 | S8: 0 | T8: 0 | U8: 0 | V8: 0 | W8: 0 | X8: 0 | Y8: 0 | Z8: 0 | AA8: 0 | AB8: -0.875 | AC8: 0 | AD8: 0 | AE8: 0 | AF8: 0 | AG8: 0 | AH8: 0 | AI8: 0 | AJ8: 0 | AK8: 0 | AL8: 0 | AM8: 0 | AN8: 0 | AO8: 0 | AP8: 0 | AQ8: 0 | AR8: 0 | AS8: 0 | AT8: 0 | AU8: 0 | AV8: 0 | AW8: 0 | AX8: 0 | AY8: 0 | AZ8: 0 | BA8: 0 | BB8: 0 | BC8: 0 | BD8: 0 | BE8: 0 | BF8: 0 | BG8: 0 | BH8: 0 | BI8: 0 | BJ8: -1.125 | BK8: 0 | BL8: -0.875 | BM8: 0 | BN8: 0 | BO8: 0 | BP8: 0 | BQ8: 0 | BR8: -0.875 | BS8: 0 | BT8: 0 | BU8: 0 | BV8: 0 | BW8: 0 | BX8: 0 | BY8: 0 | BZ8: 0 | CA8: 0 | CB8: 0 | CC8: -1.125 | CD8: 0 | CE8: 0 | CF8: 0 | CG8: 0 | CH8: 0 | CI8: 0 | CJ8: 0 | CK8: 0 | CL8: 0 | CM8: 0 | CN8: 0 | CO8: 0 | CP8: 0 | CQ8: 0 | CR8: 0 | CS8: 0 | CT8: 0 | CU8: 0 | CV8: 0 | CW8: 0 | CX8: 0 | CY8: 0 | CZ8: 0 | DA8: 0 | DB8: 0 | DC8: 0 | DD8: 0 | DE8: 0 | DF8: 0 | DG8: 0 | DH8: 0 | DI8: 0 | DJ8: 0 | DK8: 0 | DL8: 0 | DM8: 0 | DN8: 0 | DO8: 0 | DP8: 0 | DQ8: 0 | DR8: 0 | DS8: 0 | DT8: 0 | DU8: 0 | DV8: 0 | DW8: 0 | DX8: 0 | DY8: 0 | DZ8: 0 | EA8: 0 | EB8: 0 | EC8: 0 | ED8: 0 | EE8: -0.875 | EF8: 0 | EG8: 0 | EH8: -6.625 | EI8: {=VLOOKUP(A8,'Opponent List'!$A1:$P137,16,FALSE)} -> 4.1312668 | EJ8: -2.493831
A9: Arkansas | B9: 0 | C9: 0 | D9: 0 | E9: 0 | F9: 0 | G9: 0 | H9: 0 | I9: 0 | J9: 0 | K9: 0 | L9: 0 | M9: 0 | N9: 0 | O9: 0 | P9: 0 | Q9: 0 | R9: 0 | S9: 0 | T9: 0 | U9: 0 | V9: 0 | W9: 0 | X9: 0 | Y9: 0 | Z9: 0 | AA9: 0 | AB9: 0 | AC9: 0 | AD9: 0 | AE9: 0 | AF9: 0 | AG9: 0 | AH9: 0 | AI9: 0 | AJ9: 0 | AK9: 0 | AL9: 0 | AM9: 0 | AN9: 1.125 | AO9: 0 | AP9: 0 | AQ9: 1.125 | AR9: 0 | AS9: 0 | AT9: 0 | AU9: 0 | AV9: 0 | AW9: 0 | AX9: 0.25 | AY9: 0 | AZ9: 0 | BA9: 0 | BB9: 0 | BC9: 0 | BD9: 0 | BE9: 0 | BF9: 0 | BG9: 0 | BH9: 0 | BI9: 0 | BJ9: 0 | BK9: 0 | BL9: 0 | BM9: 0 | BN9: 0 | BO9: 0 | BP9: 0 | BQ9: 0 | BR9: 0 | BS9: 0 | BT9: 0 | BU9: 0 | BV9: 0 | BW9: 0 | BX9: 0 | BY9: 0 | BZ9: 0 | CA9: 0 | CB9: 0 | CC9: 0 | CD9: 0 | CE9: 0 | CF9: 0 | CG9: 0 | CH9: 0 | CI9: 0 | CJ9: 0 | CK9: 0 | CL9: -1.125 | CM9: 0 | CN9: 0 | CO9: 0 | CP9: 0 | CQ9: 0 | CR9: 0 | CS9: 1.125 | CT9: 0 | CU9: 0 | CV9: 0 | CW9: 0 | CX9: 0 | CY9: 0 | CZ9: 0 | DA9: 0 | DB9: 0 | DC9: 0 | DD9: -1.125 | DE9: 0 | DF9: 0 | DG9: 0 | DH9: 0 | DI9: 0 | DJ9: 0 | DK9: 0 | DL9: 0 | DM9: 0 | DN9: 0 | DO9: 0 | DP9: 0 | DQ9: 0 | DR9: 0 | DS9: 0 | DT9: 0 | DU9: 0 | DV9: 0 | DW9: 0 | DX9: 0 | DY9: 0 | DZ9: 0 | EA9: 0 | EB9: 0 | EC9: 0 | ED9: 0 | EE9: 0 | EF9: 0 | EG9: 0 | EH9: 1.375 | EI9: {=VLOOKUP(A9,'Opponent List'!$A1:$P137,16,FALSE)} -> -1.9174556 | EJ9: -0.54225691
A10: Army | B10: 0 | C10: 0 | D10: 0 | E10: 0 | F10: 0 | G10: 0 | H10: 0 | I10: 0 | J10: 0 | K10: 0 | L10: 0 | M10: 0.875 | N10: 0 | O10: 0 | P10: 0 | Q10: 0.875 | R10: 0 | S10: 0 | T10: 0 | U10: 0 | V10: 0 | W10: 0 | X10: 0 | Y10: 0 | Z10: 0 | AA10: 0 | AB10: 0 | AC10: 0 | AD10: 0 | AE10: 0 | AF10: 0 | AG10: 0 | AH10: 0 | AI10: 0 | AJ10: 0 | AK10: 0 | AL10: 0 | AM10: 0 | AN10: 0 | AO10: 0 | AP10: -0.875 | AQ10: 0 | AR10: 0 | AS10: 0 | AT10: 0 | AU10: 0 | AV10: 0 | AW10: 0 | AX10: 0 | AY10: 0 | AZ10: 0 | BA10: 0 | BB10: 0 | BC10: 0 | BD10: 0 | BE10: 0 | BF10: 0 | BG10: 1.125 | BH10: 0 | BI10: 0 | BJ10: 0 | BK10: 0 | BL10: 0 | BM10: 0 | BN10: 0 | BO10: 0 | BP10: 0 | BQ10: 0 | BR10: 0 | BS10: 0 | BT10: 0 | BU10: 0 | BV10: 0 | BW10: 0 | BX10: 0 | BY10: 0 | BZ10: 0 | CA10: 0 | CB10: 0 | CC10: 0 | CD10: 0 | CE10: 0 | CF10: 0 | CG10: 0 | CH10: 0 | CI10: 0 | CJ10: 0 | CK10: 0 | CL10: 0 | CM10: 0 | CN10: 0 | CO10: 0 | CP10: 0 | CQ10: 0 | CR10: 0 | CS10: 0 | CT10: 0 | CU10: 0 | CV10: 0 | CW10: 0 | CX10: 0 | CY10: 0 | CZ10: -1.125 | DA10: 0 | DB10: 0 | DC10: -0.875 | DD10: 0 | DE10: 0 | DF10: 0 | DG10: 0 | DH10: 0 | DI10: 0 | DJ10: 0 | DK10: 0 | DL10: 0 | DM10: 0 | DN10: 0 | DO10: 0 | DP10: 1.125 | DQ10: 0 | DR10: 0 | DS10: 0 | DT10: 0 | DU10: 0 | DV10: 0 | DW10: 0 | DX10: 0 | DY10: 0 | DZ10: 0 | EA10: 0 | EB10: 0 | EC10: 0 | ED10: 0 | EE10: 0 | EF10: 0 | EG10: 0 | EH10: 1.125 | EI10: {=VLOOKUP(A10,'Opponent List'!$A1:$P137,16,FALSE)} -> -1.5958247 | EJ10: -0.47110028
A11: Auburn | B11: 0 | C11: 0 | D11: 0 | E11: 0 | F11: 0 | G11: 0 | H11: 0 | I11: 0 | J11: 0 | K11: 0 | L11: 0 | M11: 0 | N11: 0 | O11: 0 | P11: 0 | Q11: 0 | R11: 0 | S11: 0 | T11: 0 | U11: 0 | V11: 0 | W11: 0 | X11: 0 | Y11: 0.875 | Z11: 0 | AA11: 0 | AB11: 0 | AC11: 0 | AD11: 0 | AE11: 0 | AF11: 0 | AG11: 0 | AH11: 0 | AI11: 0 | AJ11: 0 | AK11: 0 | AL11: 0 | AM11: 0 | AN11: 0 | AO11: 0 | AP11: 0 | AQ11: 0 | AR11: 0 | AS11: 0 | AT11: 0 | AU11: 0 | AV11: 0 | AW11: 0 | AX11: 0 | AY11: 0 | AZ11: 0 | BA11: 0 | BB11: 0 | BC11: 0 | BD11: 0 | BE11: 0 | BF11: 0 | BG11: 0 | BH11: 0 | BI11: 0 | BJ11: 0 | BK11: 0 | BL11: 0 | BM11: 0 | BN11: 0 | BO11: 0 | BP11: 0 | BQ11: 0 | BR11: 0 | BS11: 0 | BT11: 0 | BU11: 0 | BV11: 0 | BW11: 0 | BX11: 0 | BY11: 0.875 | BZ11: 0 | CA11: 0 | CB11: 0 | CC11: 0 | CD11: 0 | CE11: 0 | CF11: 0 | CG11: 0 | CH11: 0 | CI11: 0 | CJ11: 0 | CK11: 0 | CL11: 0 | CM11: 0 | CN11: 0 | CO11: 0 | CP11: 0.875 | CQ11: 0 | CR11: 0 | CS11: 1.125 | CT11: 0 | CU11: 0 | CV11: 0 | CW11: 0 | CX11: 1.125 | CY11: 0 | CZ11: 0 | DA11: 0 | DB11: -1.125 | DC11: 0 | DD11: 0 | DE11: 0 | DF11: 0 | DG11: 0 | DH11: 0 | DI11: 0 | DJ11: 0 | DK11: 0 | DL11: 0 | DM11: 0 | DN11: 0 | DO11: 0 | DP11: 0 | DQ11: 0 | DR11: 0 | DS11: 0 | DT11: 0 | DU11: 0 | DV11: 0 | DW11: 0 | DX11: 0 | DY11: 0 | DZ11: 0.875 | EA11: 0 | EB11: 0 | EC11: 0 | ED11: 0 | EE11: 0 | EF11: 0 | EG11: 0 | EH11: 4.625 | EI11: {=VLOOKUP(A11,'Opponent List'!$A1:$P137,16,FALSE)} -> -2.0005158 | EJ11: 2.6245914
A12: BYU | B12: 0 | C12: 0 | D12: 0 | E12: 0 | F12: 0 | G12: 0 | H12: 0.875 | I12: 0 | J12: 0 | K12: 0 | L12: 0 | M12: 0 | N12: 0 | O12: 0 | P12: 0 | Q12: 0 | R12: 0 | S12: 0 | T12: 0 | U12: 0 | V12: 0 | W12: -0.875 | X12: 0 | Y12: 0 | Z12: 0 | AA12: 0 | AB12: 0 | AC12: 0 | AD12: 0 | AE12: 0 | AF12: 1.125 | AG12: 0 | AH12: 0 | AI12: 0 | AJ12: 0 | AK12: 0.875 | AL12: 0 | AM12: 0 | AN12: 0 | AO12: 0 | AP12: 0 | AQ12: 0 | AR12: 0 | AS12: 0 | AT12: 0 | AU12: 0 | AV12: 0 | AW12: 0 | AX12: 0 | AY12: 0.875 | AZ12: 0 | BA12: 0 | BB12: 0 | BC12: 0 | BD12: 0 | BE12: 0 | BF12: 0 | BG12: 0 | BH12: 0 | BI12: 0 | BJ12: 0 | BK12: 0 | BL12: 0 | BM12: 0 | BN12: 0 | BO12: 0 | BP12: 0 | BQ12: 0 | BR12: 0 | BS12: 0 | BT12: 0 | BU12: 0 | BV12: 0 | BW12: 0 | BX12: 0 | BY12: 0 | BZ12: 0 | CA12: 0 | CB12: 0 | CC12: -1.125 | CD12: 0 | CE12: 0 | CF12: 0 | CG12: 0 | CH12: 0 | CI12: 0 | CJ12: 0 | CK12: 0 | CL12: 0 | CM12: 0 | CN12: 0 | CO12: 0 | CP12: 0 | CQ12: 0 | CR12: 0 | CS12: 0 | CT12: 0 | CU12: 0 | CV12: 0 | CW12: 0 | CX12: 0 | CY12: 0 | CZ12: 0 | DA12: 0 | DB12: 0 | DC12: 0 | DD12: 0 | DE12: 0 | DF12: 0 | DG12: 0 | DH12: 0 | DI12: 0 | DJ12: 0 | DK12: 0 | DL12: 0 | DM12: 0 | DN12: 0 | DO12: 0 | DP12: 0 | DQ12: 0 | DR12: 0 | DS12: 0 | DT12: 0 | DU12: 0 | DV12: 0 | DW12: 0 | DX12: 0 | DY12: 0 | DZ12: 0.875 | EA12: 0 | EB12: 0 | EC12: 0 | ED12: 0 | EE12: 0 | EF12: 0 | EG12: 0 | EH12: 2.625 | EI12: {=VLOOKUP(A12,'Opponent List'!$A1:$P137,16,FALSE)} -> -1.0188957 | EJ12: 1.6062412
A13: Ball St | B13: -0.875 | C13: 0 | D13: -0.875 | E13: 0 | F13: 0 | G13: 0 | H13: 0 | I13: 0 | J13: -0.875 | K13: 0 | L13: 0 | M13: 0 | N13: 0 | O13: 0 | P13: 0 | Q13: -0.875 | R13: 0 | S13: 0 | T13: 0 | U13: 0 | V13: 0 | W13: 0 | X13: 0 | Y13: 0 | Z13: 0 | AA13: 0 | AB13: 0 | AC13: 0 | AD13: 0 | AE13: 0 | AF13: 0 | AG13: 0 | AH13: 0 | AI13: 0 | AJ13: 0 | AK13: 0 | AL13: 0 | AM13: 0 | AN13: 0 | AO13: 0 | AP13: 0 | AQ13: -1.125 | AR13: 0 | AS13: 0 | AT13: 0 | AU13: 0 | AV13: 0 | AW13: 0 | AX13: 0 | AY13: 0 | AZ13: 0 | BA13: 0 | BB13: 0 | BC13: 0 | BD13: 0 | BE13: 0 | BF13: 0 | BG13: 0 | BH13: 0 | BI13: 0 | BJ13: 0 | BK13: 0 | BL13: 0 | BM13: 0 | BN13: 0 | BO13: 0 | BP13: 0 | BQ13: 0 | BR13: 0 | BS13: 0 | BT13: 0 | BU13: 0 | BV13: 0 | BW13: 0 | BX13: 0 | BY13: 0 | BZ13: 0 | CA13: 0 | CB13: 0 | CC13: 0 | CD13: 0 | CE13: 0 | CF13: 0 | CG13: 0 | CH13: 0 | CI13: 0 | CJ13: 0 | CK13: 0 | CL13: 0 | CM13: 0 | CN13: 0 | CO13: 0 | CP13: 0 | CQ13: 0 | CR13: 0 | CS13: 0 | CT13: 0 | CU13: 0 | CV13: 0 | CW13: -0.875 | CX13: 0 | CY13: 0 | CZ13: 0 | DA13: 0 | DB13: 0 | DC13: 0 | DD13: 0 | DE13: 0 | DF13: 0 | DG13: 0 | DH13: 0 | DI13: 0 | DJ13: -1.125 | DK13: 0 | DL13: 0 | DM13: 0 | DN13: 0 | DO13: 0 | DP13: 0 | DQ13: 0 | DR13: 0 | DS13: 0 | DT13: 0 | DU13: 0 | DV13: 0 | DW13: 0 | DX13: 0 | DY13: 0 | DZ13: 0 | EA13: 0 | EB13: 0 | EC13: 0 | ED13: 0 | EE13: 0 | EF13: 0 | EG13: 0 | EH13: -6.625 | EI13: {=VLOOKUP(A13,'Opponent List'!$A1:$P137,16,FALSE)} -> -1.230697 | EJ13: -7.8554102
A14: Baylor | B14: 0 | C14: 0 | D14: 0 | E14: 1.125 | F14: -1.125 | G14: 0 | H14: 0 | I14: 0 | J14: 0 | K14: 0 | L14: 0 | M14: 0 | N14: 0 | O14: 0 | P14: 0 | Q14: 0 | R14: 0 | S14: 0 | T14: 0 | U14: 0 | V14: -0.875 | W14: 0 | X14: 0 | Y14: 0 | Z14: 0 | AA14: 0 | AB14: 0 | AC14: 0 | AD14: 0 | AE14: 0 | AF14: 0 | AG14: 0 | AH14: 0 | AI14: 0 | AJ14: 0 | AK14: 0 | AL14: 0 | AM14: 0 | AN14: 0 | AO14: 0 | AP14: 0 | AQ14: 0 | AR14: 0 | AS14: -0.875 | AT14: 0 | AU14: 0 | AV14: 0 | AW14: 0 | AX14: 0 | AY14: 0 | AZ14: 0 | BA14: 0 | BB14: 0 | BC14: 0 | BD14: 0 | BE14: 0 | BF14: 0 | BG14: 0 | BH14: 0 | BI14: 0 | BJ14: 0 | BK14: 0 | BL14: 0 | BM14: 0.875 | BN14: 0 | BO14: 0 | BP14: 0 | BQ14: 0 | BR14: 0 | BS14: 0 | BT14: 0 | BU14: 0 | BV14: 0 | BW14: 0 | BX14: 0 | BY14: 0 | BZ14: 0 | CA14: 0 | CB14: 0 | CC14: 0 | CD14: 0 | CE14: 0 | CF14: 0 | CG14: 0 | CH14: 0 | CI14: 0 | CJ14: 0 | CK14: 0 | CL14: 0 | CM14: -0.875 | CN14: 0 | CO14: 0 | CP14: 0 | CQ14: 0 | CR14: 0 | CS14: 0 | CT14: 0 | CU14: 0 | CV14: 0 | CW14: 0 | CX14: 0 | CY14: 0 | CZ14: 0 | DA14: 0 | DB14: 0 | DC14: 0 | DD14: 0 | DE14: 0 | DF14: 0 | DG14: 0 | DH14: 0 | DI14: 0 | DJ14: 0 | DK14: 0 | DL14: 0 | DM14: 0 | DN14: 0 | DO14: 0 | DP14: 0 | DQ14: 0 | DR14: 0 | DS14: 0 | DT14: 0 | DU14: 0 | DV14: 0 | DW14: 0 | DX14: 0 | DY14: 0 | DZ14: 0 | EA14: 0 | EB14: 0 | EC14: 0 | ED14: 0 | EE14: 0 | EF14: 0 | EG14: 0.875 | EH14: -0.875 | EI14: {=VLOOKUP(A14,'Opponent List'!$A1:$P137,16,FALSE)} -> -1.6638482 | EJ14: -2.5388567
A15: Boise St | B15: 0 | C15: 0 | D15: 0 | E15: 0 | F15: 0 | G15: 0 | H15: 0 | I15: 0 | J15: 0 | K15: 0 | L15: 0 | M15: 0 | N15: 0 | O15: 0 | P15: 0 | Q15: 0 | R15: 0 | S15: 0 | T15: 0 | U15: 0 | V15: 0 | W15: 0 | X15: 0 | Y15: 0 | Z15: 0 | AA15: 0 | AB15: 0 | AC15: 0 | AD15: 0 | AE15: 0 | AF15: 0 | AG15: 0 | AH15: 0 | AI15: 0 | AJ15: 0 | AK15: 0 | AL15: 0 | AM15: 0 | AN15: 0 | AO15: 0 | AP15: 0 | AQ15: 0 | AR15: 0 | AS15: 0 | AT15: 0 | AU15: 0 | AV15: 0 | AW15: 0 | AX15: 0 | AY15: 0 | AZ15: 0 | BA15: 0 | BB15: 0 | BC15: 0 | BD15: 0 | BE15: 0 | BF15: 0 | BG15: 0 | BH15: 0 | BI15: 0 | BJ15: 0 | BK15: 0 | BL15: 0 | BM15: 0 | BN15: 0 | BO15: 0 | BP15: 0 | BQ15: 0 | BR15: 0 | BS15: 0 | BT15: 0 | BU15: 0 | BV15: 0 | BW15: 0 | BX15: 0 | BY15: 0 | BZ15: 0 | CA15: -0.875 | CB15: 0 | CC15: 0 | CD15: 0 | CE15: 0 | CF15: 1.125 | CG15: 0 | CH15: 1.125 | CI15: 0 | CJ15: 0 | CK15: 0 | CL15: 0 | CM15: 0 | CN15: 0 | CO15: 0 | CP15: 0 | CQ15: 0 | CR15: 0 | CS15: 0 | CT15: 0 | CU15: 0 | CV15: 0 | CW15: 0 | CX15: 0 | CY15: 0 | CZ15: 0 | DA15: 0 | DB15: 0 | DC15: -1.125 | DD15: 0 | DE15: 0 | DF15: 0 | DG15: -1.125 | DH15: 0 | DI15: 0 | DJ15: 0 | DK15: 0 | DL15: 0 | DM15: 0 | DN15: 0 | DO15: 0 | DP15: 0 | DQ15: 0 | DR15: 0 | DS15: 0 | DT15: 0 | DU15: 0 | DV15: 0 | DW15: 0 | DX15: 0 | DY15: 0.875 | DZ15: 0 | EA15: 0 | EB15: 0 | EC15: 0 | ED15: 0 | EE15: -0.875 | EF15: 0 | EG15: 0 | EH15: -0.875 | EI15: {=VLOOKUP(A15,'Opponent List'!$A1:$P137,16,FALSE)} -> 1.538996 | EJ15: 0.66379484
A16: Boston College | B16: 0 | C16: 0 | D16: 0 | E16: 0 | F16: 0 | G16: 0 | H16: 0 | I16: 0 | J16: 0 | K16: 0 | L16: 0 | M16: 0 | N16: 0 | O16: 0 | P16: 0 | Q16: 0 | R16: 0 | S16: 0 | T16: 0 | U16: 0 | V16: 0 | W16: 0 | X16: 0 | Y16: 0 | Z16: 0 | AA16: 0 | AB16: 0 | AC16: 0 | AD16: 0 | AE16: 1.125 | AF16: 0 | AG16: 0 | AH16: 0 | AI16: 0 | AJ16: 0 | AK16: 0 | AL16: 0 | AM16: 0 | AN16: 0 | AO16: 0.875 | AP16: 0 | AQ16: 0 | AR16: 0 | AS16: 0 | AT16: 0 | AU16: 0 | AV16: 0 | AW16: 0 | AX16: 0 | AY16: 0 | AZ16: 0 | BA16: 0 | BB16: 0 | BC16: 0 | BD16: 0 | BE16: 0 | BF16: 0 | BG16: 0 | BH16: 0 | BI16: -1.125 | BJ16: 0 | BK16: 0 | BL16: 0 | BM16: 0 | BN16: 0 | BO16: -0.875 | BP16: 0 | BQ16: 0 | BR16: 0 | BS16: 0 | BT16: 0 | BU16: 0 | BV16: -1.125 | BW16: 0 | BX16: 0 | BY16: 0 | BZ16: 0 | CA16: 0 | CB16: 0 | CC16: 0 | CD16: 0 | CE16: 0 | CF16: 0 | CG16: 0 | CH16: 0 | CI16: 0 | CJ16: 0 | CK16: 0 | CL16: 0 | CM16: 0 | CN16: 0 | CO16: 0 | CP16: 0.875 | CQ16: 0 | CR16: 0 | CS16: 0 | CT16: 0 | CU16: 0 | CV16: 0 | CW16: 0 | CX16: 0 | CY16: 0 | CZ16: 0 | DA16: 0 | DB16: 0 | DC16: 0 | DD16: 0 | DE16: 0 | DF16: 0 | DG16: 0 | DH16: 0 | DI16: 0 | DJ16: 0 | DK16: 0 | DL16: 0 | DM16: 0 | DN16: 0 | DO16: 0 | DP16: 0 | DQ16: 0 | DR16: 0 | DS16: 0 | DT16: 0 | DU16: 1.125 | DV16: 0 | DW16: 0 | DX16: 0 | DY16: 0 | DZ16: 0 | EA16: 0 | EB16: 0 | EC16: 0 | ED16: 0 | EE16: 0 | EF16: 0 | EG16: 0 | EH16: 0.875 | EI16: {=VLOOKUP(A16,'Opponent List'!$A1:$P137,16,FALSE)} -> -1.3400364 | EJ16: -0.46501956
A17: Bowling Green | B17: 0 | C17: 0 | D17: 0 | E17: 0 | F17: 0 | G17: 0 | H17: 0 | I17: 0 | J17: -0.875 | K17: 0 | L17: 0 | M17: 0.875 | N17: 0 | O17: 0 | P17: 0 | Q17: 0 | R17: 0 | S17: 0 | T17: 0 | U17: 0 | V17: 0 | W17: 0 | X17: 0 | Y17: 0 | Z17: 0 | AA17: -0.875 | AB17: 0 | AC17: -1.125 | AD17: 0 | AE17: 0 | AF17: 0 | AG17: 0 | AH17: 0 | AI17: 0 | AJ17: 0 | AK17: 0 | AL17: 0 | AM17: 0 | AN17: 0 | AO17: 0 | AP17: 0 | AQ17: -0.875 | AR17: 0 | AS17: 0 | AT17: 0 | AU17: 0 | AV17: 0 | AW17: 0 | AX17: 0 | AY17: 0 | AZ17: 0 | BA17: 0 | BB17: 0 | BC17: 0 | BD17: -1.125 | BE17: 0 | BF17: 0 | BG17: 0 | BH17: 0 | BI17: 0 | BJ17: 0 | BK17: 0 | BL17: 0 | BM17: 0 | BN17: -0.875 | BO17: 0 | BP17: 0 | BQ17: 0 | BR17: 0 | BS17: 0 | BT17: 0 | BU17: 0 | BV17: 0 | BW17: 0 | BX17: 0 | BY17: 0 | BZ17: 0 | CA17: 0 | CB17: 0 | CC17: 0 | CD17: 0 | CE17: 0 | CF17: 0 | CG17: 0 | CH17: 0 | CI17: 0 | CJ17: 0 | CK17: 0 | CL17: 0 | CM17: 0 | CN17: 0 | CO17: 0 | CP17: 0 | CQ17: 0 | CR17: 0 | CS17: 0 | CT17: 0 | CU17: 0 | CV17: 0 | CW17: 0 | CX17: 0 | CY17: 0 | CZ17: 0 | DA17: 0 | DB17: 0 | DC17: 0 | DD17: 0 | DE17: 0 | DF17: 0 | DG17: 0 | DH17: 0 | DI17: 0 | DJ17: 0 | DK17: 0 | DL17: 0 | DM17: 0 | DN17: 0 | DO17: 0 | DP17: 0 | DQ17: 0 | DR17: 0 | DS17: 0 | DT17: 0 | DU17: 0 | DV17: 0 | DW17: 0 | DX17: 0 | DY17: 0 | DZ17: 0 | EA17: 0 | EB17: 0 | EC17: 0 | ED17: 0 | EE17: 0 | EF17: 0 | EG17: 0 | EH17: -4.875 | EI17: {=VLOOKUP(A17,'Opponent List'!$A1:$P137,16,FALSE)} -> -1.9825822 | EJ17: -6.8572925
A18: Buffalo | B18: 0 | C18: 0 | D18: 0 | E18: 0 | F18: 0 | G18: 0 | H18: 0 | I18: 0 | J18: 0 | K18: 0 | L18: 0 | M18: 0 | N18: 0 | O18: 0 | P18: 0 | Q18: 0 | R18: 0 | S18: 0 | T18: 0 | U18: 0 | V18: 0 | W18: 0 | X18: 0 | Y18: 0 | Z18: 0 | AA18: 0 | AB18: 0 | AC18: 0 | AD18: 0.875 | AE18: 0.875 | AF18: 0 | AG18: 0 | AH18: -1.125 | AI18: 0 | AJ18: 0 | AK18: 0 | AL18: 0 | AM18: 0 | AN18: 0 | AO18: 0 | AP18: 0 | AQ18: 0 | AR18: 0 | AS18: 0 | AT18: 0 | AU18: 0 | AV18: 0 | AW18: 0 | AX18: 0 | AY18: 0 | AZ18: 0 | BA18: 0 | BB18: 0 | BC18: 0 | BD18: 0 | BE18: 0 | BF18: 0 | BG18: 0 | BH18: 0 | BI18: 0 | BJ18: 0 | BK18: 0 | BL18: 0 | BM18: 0 | BN18: 0 | BO18: 0 | BP18: 0 | BQ18: 0 | BR18: 0 | BS18: 0 | BT18: 0 | BU18: 0 | BV18: 0 | BW18: 0 | BX18: 0 | BY18: 0 | BZ18: 0 | CA18: 0 | CB18: 0 | CC18: 0 | CD18: 0 | CE18: 0.875 | CF18: 0 | CG18: 0 | CH18: 0 | CI18: -0.875 | CJ18: 0 | CK18: 0 | CL18: 0 | CM18: 0 | CN18: 0 | CO18: 0 | CP18: 0 | CQ18: 0 | CR18: 0 | CS18: 0 | CT18: 0 | CU18: 0 | CV18: 0 | CW18: 0 | CX18: 0 | CY18: 0 | CZ18: 0 | DA18: 0 | DB18: 0 | DC18: 0 | DD18: 0 | DE18: 0 | DF18: 0 | DG18: 0 | DH18: 0 | DI18: 0 | DJ18: 0 | DK18: 0 | DL18: 0 | DM18: 0 | DN18: 0 | DO18: 1.125 | DP18: 0 | DQ18: 0 | DR18: 0 | DS18: 0 | DT18: 0 | DU18: 0 | DV18: 0 | DW18: 0 | DX18: 0 | DY18: 0 | DZ18: 0 | EA18: 0 | EB18: 0 | EC18: 0 | ED18: 0 | EE18: 0 | EF18: 1.125 | EG18: 0 | EH18: 2.875 | EI18: {=VLOOKUP(A18,'Opponent List'!$A1:$P137,16,FALSE)} -> -0.7178004 | EJ18: 2.1571893
A19: C Michigan | B19: 0 | C19: 0 | D19: 0 | E19: 0 | F19: 0 | G19: 0 | H19: 0 | I19: 0 | J19: 0 | K19: 0 | L19: 0 | M19: 0 | N19: 0 | O19: 0 | P19: 0 | Q19: 0 | R19: 0 | S19: 0 | T19: 0 | U19: 0 | V19: 0 | W19: 0 | X19: 0.875 | Y19: 0 | Z19: 0 | AA19: 0 | AB19: 0 | AC19: -1.125 | AD19: 0 | AE19: 0 | AF19: 0 | AG19: 0 | AH19: 0 | AI19: 0 | AJ19: 0.875 | AK19: 1.125 | AL19: 0 | AM19: 0 | AN19: 0 | AO19: 0 | AP19: 0 | AQ19: 0 | AR19: 0 | AS19: 0 | AT19: 0 | AU19: 0 | AV19: 0 | AW19: 0 | AX19: 0 | AY19: 0 | AZ19: 0 | BA19: 0 | BB19: 0 | BC19: 0 | BD19: 0 | BE19: 0 | BF19: 0 | BG19: 0 | BH19: 0 | BI19: 0 | BJ19: 0 | BK19: 0 | BL19: 0 | BM19: 0 | BN19: 0 | BO19: 0 | BP19: 0 | BQ19: 0 | BR19: 0 | BS19: 0 | BT19: 0 | BU19: 0 | BV19: 0 | BW19: 0 | BX19: 0 | BY19: 0 | BZ19: 0 | CA19: 0 | CB19: -1.125 | CC19: 0 | CD19: 0 | CE19: 0 | CF19: 0 | CG19: 0 | CH19: 0 | CI19: 0 | CJ19: 0 | CK19: 0 | CL19: 0 | CM19: 0 | CN19: -0.875 | CO19: 0 | CP19: 0 | CQ19: -1.125 | CR19: 0 | CS19: 0 | CT19: 0 | CU19: 0 | CV19: 0 | CW19: 0 | CX19: 0 | CY19: 0 | CZ19: 0 | DA19: 0 | DB19: 0 | DC19: 0 | DD19: 0 | DE19: 0 | DF19: 0 | DG19: 0 | DH19: 0 | DI19: 0 | DJ19: 0 | DK19: 0 | DL19: 0 | DM19: 0 | DN19: 0 | DO19: 0 | DP19: 0 | DQ19: 0 | DR19: 0 | DS19: 0 | DT19: 0 | DU19: 0 | DV19: 0 | DW19: 0 | DX19: 0 | DY19: 0 | DZ19: 0 | EA19: 0 | EB19: 0 | EC19: 0 | ED19: 0 | EE19: 0 | EF19: 0 | EG19: 0 | EH19: -1.375 | EI19: {=VLOOKUP(A19,'Opponent List'!$A1:$P137,16,FALSE)} -> -2.4021072 | EJ19: -3.7770901
A20: California | B20: 0 | C20: 0 | D20: 0 | E20: 0 | F20: 0 | G20: 0 | H20: 0 | I20: 0 | J20: 0 | K20: 0 | L20: 0 | M20: 0 | N20: 0 | O20: 0 | P20: 0 | Q20: 0 | R20: 0 | S20: 0 | T20: 0 | U20: 0 | V20: 0 | W20: 0 | X20: 0 | Y20: 0 | Z20: 0 | AA20: 0 | AB20: 0 | AC20: 0 | AD20: 0 | AE20: 0 | AF20: 0 | AG20: 0 | AH20: 0 | AI20: 0 | AJ20: 0 | AK20: 0 | AL20: 0 | AM20: 0 | AN20: 0 | AO20: 0 | AP20: 0 | AQ20: 0 | AR20: 0 | AS20: 0 | AT20: 0 | AU20: 0.875 | AV20: 0 | AW20: 0 | AX20: 0 | AY20: 0 | AZ20: 0 | BA20: 0 | BB20: 0 | BC20: 0 | BD20: 0 | BE20: 0 | BF20: 0 | BG20: 0 | BH20: 0 | BI20: 0 | BJ20: 0 | BK20: 0 | BL20: 0 | BM20: 0 | BN20: 0 | BO20: 0 | BP20: 0 | BQ20: 0.875 | BR20: 0 | BS20: 0 | BT20: 0 | BU20: 0 | BV20: 0 | BW20: 0 | BX20: 0 | BY20: 0 | BZ20: 0 | CA20: 0 | CB20: 0 | CC20: 0 | CD20: 0 | CE20: 0 | CF20: 0 | CG20: -1.125 | CH20: 0 | CI20: 0 | CJ20: 0 | CK20: 0 | CL20: 0 | CM20: 0 | CN20: 0 | CO20: 0 | CP20: 0 | CQ20: 0 | CR20: 0 | CS20: 0 | CT20: 0 | CU20: 0 | CV20: 0 | CW20: 0 | CX20: 0 | CY20: 0 | CZ20: 0 | DA20: 0 | DB20: 0 | DC20: 0 | DD20: 0 | DE20: 0 | DF20: 0 | DG20: 0 | DH20: 0 | DI20: 0 | DJ20: 0.875 | DK20: 0 | DL20: 0 | DM20: 0 | DN20: -0.875 | DO20: 0 | DP20: 0 | DQ20: 0 | DR20: 0 | DS20: 0 | DT20: 0 | DU20: 0 | DV20: 0 | DW20: 0 | DX20: 0 | DY20: 0 | DZ20: 0 | EA20: -0.875 | EB20: 0 | EC20: 0 | ED20: 0 | EE20: 0 | EF20: 0 | EG20: 1.125 | EH20: 0.875 | EI20: {=VLOOKUP(A20,'Opponent List'!$A1:$P137,16,FALSE)} -> -0.85655769 | EJ20: 0.018556443
A21: Charlotte | B21: 0 | C21: 0 | D21: 0 | E21: 0 | F21: 0 | G21: 0 | H21: 0 | I21: 0 | J21: 0 | K21: 0 | L21: 0 | M21: 0 | N21: 0 | O21: 0 | P21: 0 | Q21: 0 | R21: 0 | S21: 0 | T21: 0 | U21: 0 | V21: 0 | W21: 0 | X21: 0 | Y21: -1.125 | Z21: 0 | AA21: 0 | AB21: 0 | AC21: 0 | AD21: 0 | AE21: 0 | AF21: 0 | AG21: 0 | AH21: 0 | AI21: 0 | AJ21: 0 | AK21: 0 | AL21: 0 | AM21: 0 | AN21: 0 | AO21: 0 | AP21: 0 | AQ21: 0 | AR21: -0.875 | AS21: 0 | AT21: 0 | AU21: 0 | AV21: -1.125 | AW21: 0 | AX21: 0 | AY21: 0 | AZ21: 0 | BA21: 0 | BB21: 0 | BC21: 0 | BD21: 0 | BE21: 0 | BF21: 0 | BG21: 0 | BH21: 0 | BI21: 0 | BJ21: -0.875 | BK21: 0 | BL21: 0 | BM21: 0 | BN21: 0 | BO21: -0.875 | BP21: 0 | BQ21: 0 | BR21: 0 | BS21: 0 | BT21: 0 | BU21: 0 | BV21: 0 | BW21: 0 | BX21: 0 | BY21: 0 | BZ21: 0 | CA21: 0 | CB21: 0 | CC21: 0 | CD21: 0 | CE21: 0 | CF21: 0 | CG21: 0 | CH21: 0 | CI21: 0 | CJ21: 0 | CK21: 0 | CL21: -0.875 | CM21: 0 | CN21: 0 | CO21: 0 | CP21: 0 | CQ21: 0 | CR21: 0 | CS21: 0 | CT21: 0 | CU21: 0 | CV21: 0 | CW21: 0 | CX21: 0 | CY21: 0 | CZ21: 0 | DA21: 0 | DB21: 0 | DC21: 0 | DD21: 0 | DE21: 0 | DF21: 0 | DG21: 0 | DH21: 0 | DI21: 0 | DJ21: 0 | DK21: 0 | DL21: 0 | DM21: 0 | DN21: 0 | DO21: 0 | DP21: 0 | DQ21: 0 | DR21: 0 | DS21: 0 | DT21: 0 | DU21: 0 | DV21: -1.125 | DW21: 0 | DX21: 0 | DY21: 0 | DZ21: 0 | EA21: 0 | EB21: 0 | EC21: 0 | ED21: 0 | EE21: 0 | EF21: 0 | EG21: 0 | EH21: -6.875 | EI21: {=VLOOKUP(A21,'Opponent List'!$A1:$P137,16,FALSE)} -> 2.4112763 | EJ21: -4.4638144
A22: Cincinnati | B22: 0 | C22: 0 | D22: 0 | E22: 0 | F22: 0 | G22: 0 | H22: 0 | I22: 0 | J22: 0 | K22: 0 | L22: 0 | M22: 0 | N22: 0.875 | O22: 0 | P22: 0 | Q22: 0 | R22: 0 | S22: 0 | T22: 0 | U22: 0 | V22: 0 | W22: 0 | X22: 0 | Y22: 0 | Z22: 0 | AA22: 0 | AB22: 0 | AC22: 0 | AD22: 0 | AE22: 0 | AF22: 0 | AG22: 0 | AH22: 0 | AI22: 0.875 | AJ22: 0 | AK22: 0 | AL22: 0 | AM22: 0 | AN22: 0 | AO22: 0 | AP22: 0 | AQ22: 0 | AR22: 0 | AS22: 0 | AT22: 0 | AU22: 0 | AV22: 0 | AW22: 0 | AX22: 0 | AY22: 0 | AZ22: 0 | BA22: 0 | BB22: 0 | BC22: 0 | BD22: 1.125 | BE22: 0 | BF22: 0 | BG22: 0 | BH22: 0 | BI22: 0 | BJ22: 0 | BK22: 0 | BL22: 0 | BM22: 0.875 | BN22: 0 | BO22: 0 | BP22: 0 | BQ22: 0 | BR22: 0 | BS22: 0 | BT22: 0 | BU22: 0 | BV22: 0 | BW22: 0 | BX22: 0 | BY22: 0 | BZ22: 0 | CA22: 0 | CB22: 0 | CC22: 0 | CD22: 0 | CE22: 0 | CF22: 0 | CG22: 0 | CH22: 0 | CI22: 0 | CJ22: 0 | CK22: 0 | CL22: 0 | CM22: 0 | CN22: 0 | CO22: 1.125 | CP22: 0 | CQ22: 0 | CR22: 0 | CS22: 0 | CT22: 0 | CU22: 0 | CV22: 0 | CW22: 0 | CX22: 0 | CY22: 0 | CZ22: 0 | DA22: 0 | DB22: 0 | DC22: 0 | DD22: 0 | DE22: 0 | DF22: 0 | DG22: 0 | DH22: 0 | DI22: 0 | DJ22: 0 | DK22: 0 | DL22: 0 | DM22: 0 | DN22: 0 | DO22: 0 | DP22: 0 | DQ22: 0 | DR22: 0 | DS22: 0 | DT22: 0 | DU22: 0 | DV22: 0 | DW22: 0 | DX22: 0 | DY22: 0 | DZ22: 0 | EA22: 0 | EB22: 0 | EC22: 0 | ED22: 0 | EE22: 0 | EF22: 0 | EG22: 0 | EH22: 4.875 | EI22: {=VLOOKUP(A22,'Opponent List'!$A1:$P137,16,FALSE)} -> -3.4151591 | EJ22: 1.4600486
A23: Clemson | B23: 0 | C23: 0 | D23: 0 | E23: 0 | F23: 0 | G23: 0 | H23: 0 | I23: 0 | J23: 0 | K23: 0 | L23: 0.875 | M23: 0 | N23: 0 | O23: 0 | P23: 0 | Q23: 0 | R23: 0 | S23: 0 | T23: 0 | U23: 0 | V23: 0 | W23: 0 | X23: 0 | Y23: 0 | Z23: 0 | AA23: 0 | AB23: 0 | AC23: 0 | AD23: 0 | AE23: 0 | AF23: 0 | AG23: 0 | AH23: 0 | AI23: 0 | AJ23: 0 | AK23: 0 | AL23: 0 | AM23: -1.125 | AN23: 0 | AO23: 0 | AP23: 0 | AQ23: 0 | AR23: 0 | AS23: 0 | AT23: 0 | AU23: 0 | AV23: 0 | AW23: 0 | AX23: 0 | AY23: 0 | AZ23: 0 | BA23: 0 | BB23: 0 | BC23: 0 | BD23: 0 | BE23: 0 | BF23: 0 | BG23: -1.125 | BH23: 0 | BI23: 0 | BJ23: 0 | BK23: 0 | BL23: 0 | BM23: 0 | BN23: 0 | BO23: 0 | BP23: 0 | BQ23: 0 | BR23: 0 | BS23: 0 | BT23: 0 | BU23: 0 | BV23: 0 | BW23: 0 | BX23: 0 | BY23: 0 | BZ23: 0 | CA23: 0 | CB23: 0 | CC23: 0 | CD23: 0 | CE23: 0 | CF23: 0 | CG23: 0 | CH23: 0 | CI23: 0 | CJ23: 0 | CK23: 0 | CL23: 0 | CM23: 0 | CN23: 0 | CO23: 0 | CP23: 0 | CQ23: 0 | CR23: 0 | CS23: 0 | CT23: 0 | CU23: 0 | CV23: 0 | CW23: 0 | CX23: 0 | CY23: 1.125 | CZ23: 0 | DA23: 0 | DB23: 0 | DC23: 0 | DD23: 0 | DE23: 0 | DF23: 0 | DG23: 0 | DH23: 0 | DI23: 0 | DJ23: 0 | DK23: 0 | DL23: 0 | DM23: 0 | DN23: 0 | DO23: 0 | DP23: 0 | DQ23: 0 | DR23: 0 | DS23: 0 | DT23: 0 | DU23: 0 | DV23: 0 | DW23: 0 | DX23: 0 | DY23: 0 | DZ23: 0 | EA23: 0 | EB23: 0 | EC23: 0 | ED23: 0.875 | EE23: 0 | EF23: 0 | EG23: 0 | EH23: 0.625 | EI23: {=VLOOKUP(A23,'Opponent List'!$A1:$P137,16,FALSE)} -> 2.0034822 | EJ23: 2.6281733
A24: Coastal Car | B24: 0 | C24: 0 | D24: 0 | E24: 0 | F24: 0 | G24: 0 | H24: 0 | I24: 0 | J24: 0 | K24: 0 | L24: 0 | M24: 0 | N24: 0 | O24: 0 | P24: 0 | Q24: 0 | R24: 0 | S24: -0.875 | T24: 0 | U24: 0 | V24: 0 | W24: 0 | X24: 0 | Y24: 0 | Z24: -1.125 | AA24: 0 | AB24: 0 | AC24: 0 | AD24: 0 | AE24: 0 | AF24: 0 | AG24: 0 | AH24: 0 | AI24: 0 | AJ24: 0 | AK24: 0 | AL24: 0 | AM24: 0 | AN24: 0 | AO24: 0 | AP24: 0 | AQ24: 0 | AR24: 0 | AS24: 0 | AT24: 0 | AU24: 0 | AV24: 0 | AW24: 0 | AX24: 0 | AY24: 0 | AZ24: 0 | BA24: 0 | BB24: 0 | BC24: 0 | BD24: 0 | BE24: 0 | BF24: 0 | BG24: 0 | BH24: 0 | BI24: 0 | BJ24: 0 | BK24: 0 | BL24: 0 | BM24: 0 | BN24: -0.875 | BO24: 0 | BP24: 0 | BQ24: 0 | BR24: 0 | BS24: 0 | BT24: 0 | BU24: 0 | BV24: 0 | BW24: 0 | BX24: 0 | BY24: 0 | BZ24: 0 | CA24: 0 | CB24: 0 | CC24: 0 | CD24: 0 | CE24: 0 | CF24: 0 | CG24: 0 | CH24: 0 | CI24: 0 | CJ24: 0 | CK24: 0 | CL24: 0 | CM24: 0 | CN24: 0 | CO24: 0 | CP24: 0 | CQ24: -0.875 | CR24: 0 | CS24: 0 | CT24: 0 | CU24: 0 | CV24: 0 | CW24: 0 | CX24: 0 | CY24: 0 | CZ24: 0 | DA24: 1.125 | DB24: 0 | DC24: 0 | DD24: 0 | DE24: 0 | DF24: 0 | DG24: 0 | DH24: 0 | DI24: 0 | DJ24: 0 | DK24: 0.875 | DL24: 0 | DM24: 0 | DN24: 0 | DO24: 0 | DP24: 0 | DQ24: 0 | DR24: 0 | DS24: 0 | DT24: 0 | DU24: 0 | DV24: 0 | DW24: -1.125 | DX24: 0 | DY24: 0 | DZ24: 0 | EA24: 0 | EB24: 0 | EC24: 0 | ED24: 0 | EE24: 0 | EF24: 0 | EG24: 0 | EH24: -2.875 | EI24: {=VLOOKUP(A24,'Opponent List'!$A1:$P137,16,FALSE)} -> -1.595282 | EJ24: -4.4699921
A25: Colorado St | B25: 0 | C25: 0 | D25: 0 | E25: 0 | F25: 0 | G25: 0 | H25: 0 | I25: 0 | J25: 0 | K25: -0.875 | L25: 0 | M25: 0 | N25: 0 | O25: 0 | P25: 0 | Q25: 0 | R25: 0 | S25: 0 | T25: 0 | U25: 1.125 | V25: 0 | W25: 0 | X25: 0 | Y25: 0 | Z25: 0 | AA25: 0 | AB25: 0 | AC25: 0 | AD25: 0 | AE25: 0 | AF25: 0 | AG25: 0 | AH25: 0 | AI25: 0 | AJ25: 0 | AK25: 0 | AL25: 0 | AM25: 0 | AN25: 0 | AO25: 0 | AP25: 0 | AQ25: 0 | AR25: 0 | AS25: 0 | AT25: 0 | AU25: 0 | AV25: 0 | AW25: -1.125 | AX25: 0 | AY25: 0 | AZ25: 0 | BA25: 0 | BB25: 0 | BC25: 0 | BD25: 0 | BE25: 0 | BF25: -0.875 | BG25: 0 | BH25: 0 | BI25: 0 | BJ25: 0 | BK25: 0 | BL25: 0 | BM25: 0 | BN25: -1.125 | BO25: 0 | BP25: 0 | BQ25: 0 | BR25: 0 | BS25: 0 | BT25: 0 | BU25: 0 | BV25: 0 | BW25: -0.875 | BX25: 0 | BY25: 0 | BZ25: 0 | CA25: 0 | CB25: 0 | CC25: 0 | CD25: 0 | CE25: 0 | CF25: 0 | CG25: 0 | CH25: 0 | CI25: 0 | CJ25: 0 | CK25: 0 | CL25: 0 | CM25: 0 | CN25: 0 | CO25: 0 | CP25: 0 | CQ25: 0 | CR25: 0 | CS25: 0 | CT25: 0 | CU25: 0 | CV25: 0 | CW25: 0 | CX25: 0 | CY25: 0 | CZ25: 0 | DA25: 0 | DB25: 0 | DC25: 0 | DD25: 0 | DE25: 0 | DF25: 0 | DG25: 0 | DH25: 0 | DI25: 0 | DJ25: 0 | DK25: 0 | DL25: 0 | DM25: 0 | DN25: 0 | DO25: 0 | DP25: 0 | DQ25: 0 | DR25: 0 | DS25: 0 | DT25: 0 | DU25: 0 | DV25: 0 | DW25: 0 | DX25: 0 | DY25: 0 | DZ25: 0 | EA25: 0 | EB25: 0 | EC25: 0 | ED25: -1.125 | EE25: 0 | EF25: 0 | EG25: 0 | EH25: -4.875 | EI25: {=VLOOKUP(A25,'Opponent List'!$A1:$P137,16,FALSE)} -> 0.6803206 | EJ25: -4.1947203
A26: Colorado | B26: 0 | C26: 0 | D26: 0 | E26: 0 | F26: 0 | G26: 0 | H26: 0 | I26: 0 | J26: 0 | K26: 0 | L26: 0 | M26: 0 | N26: 0 | O26: 0 | P26: 0 | Q26: 0 | R26: 0 | S26: 0 | T26: 0 | U26: 0 | V26: 0 | W26: 0 | X26: 1.125 | Y26: 0 | Z26: 0 | AA26: 0 | AB26: 0 | AC26: 0 | AD26: 0 | AE26: 0 | AF26: 0 | AG26: 0 | AH26: 0 | AI26: 0 | AJ26: 0 | AK26: 0 | AL26: -1.125 | AM26: 0 | AN26: 0 | AO26: 0 | AP26: 0 | AQ26: 0 | AR26: 0 | AS26: 0 | AT26: 0 | AU26: 0 | AV26: 0 | AW26: 0 | AX26: 0 | AY26: 0 | AZ26: 0 | BA26: 0 | BB26: 0 | BC26: 0 | BD26: 0 | BE26: 0 | BF26: 0 | BG26: -1.125 | BH26: 0 | BI26: 0 | BJ26: 0 | BK26: 0.875 | BL26: 0 | BM26: 0 | BN26: 0 | BO26: 0 | BP26: 0 | BQ26: 0 | BR26: 0 | BS26: 0 | BT26: -1.125 | BU26: 0 | BV26: 0 | BW26: 0 | BX26: 0 | BY26: 0 | BZ26: -0.875 | CA26: 0 | CB26: 0 | CC26: 0 | CD26: 0 | CE26: 0 | CF26: 0 | CG26: 0 | CH26: 0 | CI26: 0 | CJ26: 0 | CK26: 0 | CL26: 0 | CM26: 0 | CN26: 0 | CO26: 0 | CP26: 0 | CQ26: 0 | CR26: 0 | CS26: 0 | CT26: 0 | CU26: 0 | CV26: 0 | CW26: 0 | CX26: 0 | CY26: 0 | CZ26: 0 | DA26: 0 | DB26: 0 | DC26: -0.875 | DD26: 0 | DE26: 0 | DF26: 0 | DG26: 0 | DH26: 0 | DI26: 0 | DJ26: 0 | DK26: 0 | DL26: 0 | DM26: 0 | DN26: 0 | DO26: 0 | DP26: 0 | DQ26: 0 | DR26: 0 | DS26: 0 | DT26: 0 | DU26: 0 | DV26: 0 | DW26: 0 | DX26: 0 | DY26: 0 | DZ26: 0 | EA26: 0 | EB26: 0 | EC26: 0 | ED26: 0 | EE26: 0 | EF26: 0 | EG26: 0 | EH26: -3.125 | EI26: {=VLOOKUP(A26,'Opponent List'!$A1:$P137,16,FALSE)} -> 1.2020777 | EJ26: -1.9231974
A27: Delaware | B27: 0 | C27: 0 | D27: 0 | E27: 0 | F27: 0 | G27: 0 | H27: 0 | I27: 0 | J27: 0 | K27: 0 | L27: 0 | M27: 0 | N27: 0 | O27: 0 | P27: 0 | Q27: 0.875 | R27: 0 | S27: 0 | T27: 0 | U27: 0 | V27: 0 | W27: 0 | X27: 0 | Y27: 0 | Z27: 0 | AA27: 0 | AB27: -0.875 | AC27: 0 | AD27: 0 | AE27: 0 | AF27: 0 | AG27: 0 | AH27: 0 | AI27: 0 | AJ27: 0 | AK27: 0 | AL27: 0 | AM27: 0 | AN27: 0 | AO27: 0 | AP27: 0 | AQ27: 0 | AR27: 0 | AS27: 0 | AT27: 0 | AU27: 0 | AV27: 0 | AW27: 0 | AX27: 0 | AY27: 0 | AZ27: 0 | BA27: 0 | BB27: 0 | BC27: -0.875 | BD27: 0 | BE27: 0 | BF27: 0 | BG27: 0 | BH27: 0 | BI27: 0 | BJ27: -0.875 | BK27: 0 | BL27: 0 | BM27: 0 | BN27: 0 | BO27: 0 | BP27: 0 | BQ27: 0 | BR27: 0 | BS27: 0 | BT27: 0 | BU27: 0 | BV27: 0 | BW27: 0 | BX27: 0 | BY27: 0 | BZ27: 0 | CA27: -1.125 | CB27: 0 | CC27: 0 | CD27: 0 | CE27: 0 | CF27: 0 | CG27: 0 | CH27: 0 | CI27: 0 | CJ27: 0 | CK27: 0 | CL27: 0 | CM27: 0 | CN27: 0 | CO27: 0 | CP27: 0 | CQ27: 0 | CR27: 0 | CS27: 0 | CT27: 0 | CU27: 0 | CV27: 0 | CW27: 0 | CX27: 0 | CY27: 0 | CZ27: 0 | DA27: 0 | DB27: 0 | DC27: 0 | DD27: 0 | DE27: -1.125 | DF27: 0 | DG27: 0 | DH27: 0 | DI27: 0 | DJ27: 0 | DK27: 0 | DL27: 0 | DM27: 0 | DN27: 0 | DO27: 0 | DP27: 0.875 | DQ27: 0 | DR27: 0 | DS27: 0 | DT27: 0 | DU27: 0 | DV27: 0 | DW27: 0 | DX27: 0 | DY27: 0 | DZ27: 0 | EA27: 0 | EB27: 0 | EC27: 0 | ED27: 0 | EE27: 0 | EF27: 0 | EG27: 0 | EH27: -3.125 | EI27: {=VLOOKUP(A27,'Opponent List'!$A1:$P137,16,FALSE)} -> -0.64043929 | EJ27: -3.7656245
A28: Duke | B28: 0 | C28: 0 | D28: 0 | E28: -1.125 | F28: 0 | G28: 0 | H28: 0.875 | I28: 0 | J28: 0 | K28: 0 | L28: 0 | M28: 0 | N28: 0 | O28: 0 | P28: 0 | Q28: 0 | R28: 0 | S28: 0 | T28: 0 | U28: 0 | V28: 0 | W28: 0 | X28: 0 | Y28: 0 | Z28: 0 | AA28: 0.875 | AB28: 0 | AC28: 0 | AD28: 0 | AE28: 0 | AF28: 0 | AG28: 0 | AH28: 0 | AI28: 0 | AJ28: 0 | AK28: 0 | AL28: 0 | AM28: 0 | AN28: 0 | AO28: 0 | AP28: 0 | AQ28: 0 | AR28: 0 | AS28: 0 | AT28: 0 | AU28: 0.875 | AV28: 0 | AW28: 0 | AX28: 0 | AY28: 0 | AZ28: 0 | BA28: 1.125 | BB28: 0 | BC28: 0 | BD28: 0 | BE28: 0 | BF28: 0 | BG28: 0 | BH28: 0 | BI28: 0 | BJ28: 0 | BK28: 0 | BL28: 0 | BM28: 0 | BN28: 2.25 | BO28: 0 | BP28: 0 | BQ28: 0 | BR28: 0 | BS28: 0 | BT28: 0 | BU28: 0 | BV28: 0 | BW28: 0 | BX28: 0 | BY28: 0 | BZ28: 0 | CA28: 0 | CB28: 0 | CC28: 0 | CD28: 0 | CE28: 0 | CF28: 0 | CG28: 0 | CH28: 0 | CI28: 0 | CJ28: 0 | CK28: 0 | CL28: 0 | CM28: 0 | CN28: 0 | CO28: 0 | CP28: 0 | CQ28: 0 | CR28: 0 | CS28: 0 | CT28: 0 | CU28: 0 | CV28: 0 | CW28: 0 | CX28: 0 | CY28: 0 | CZ28: 0 | DA28: 0 | DB28: 0 | DC28: 0 | DD28: 0 | DE28: 0 | DF28: 0 | DG28: 0 | DH28: 0 | DI28: 0 | DJ28: 0 | DK28: 0 | DL28: 0 | DM28: 0 | DN28: 0 | DO28: 0 | DP28: 0 | DQ28: 0 | DR28: 0 | DS28: 0 | DT28: 0 | DU28: 0 | DV28: 0 | DW28: 0 | DX28: 0 | DY28: 0 | DZ28: 0 | EA28: 0 | EB28: 0 | EC28: 0 | ED28: 0 | EE28: 0 | EF28: 0 | EG28: 0 | EH28: 4.875 | EI28: {=VLOOKUP(A28,'Opponent List'!$A1:$P137,16,FALSE)} -> -1.6806677 | EJ28: 3.1946532
A29: E Carolina | B29: 0 | C29: 0 | D29: 0 | E29: 0 | F29: 0 | G29: 0 | H29: 0 | I29: 0 | J29: 0 | K29: 0 | L29: 0 | M29: 0 | N29: 0 | O29: 0 | P29: 0 | Q29: 1.125 | R29: 0 | S29: 1.125 | T29: 0 | U29: 0 | V29: 0 | W29: 0 | X29: 0 | Y29: 0 | Z29: 0 | AA29: 0 | AB29: 0 | AC29: 0 | AD29: 0 | AE29: 0 | AF29: 0 | AG29: 0 | AH29: 0 | AI29: 0 | AJ29: 0 | AK29: 0 | AL29: 0 | AM29: 0 | AN29: 0 | AO29: 0 | AP29: 0 | AQ29: 0 | AR29: 0 | AS29: 0 | AT29: 0 | AU29: -1.125 | AV29: 0 | AW29: 0 | AX29: 0 | AY29: 0 | AZ29: 0 | BA29: 0 | BB29: 0.875 | BC29: 0 | BD29: 0 | BE29: 0 | BF29: 0 | BG29: 0 | BH29: 0 | BI29: 0 | BJ29: 0 | BK29: 0 | BL29: 0 | BM29: 0 | BN29: 0 | BO29: 0 | BP29: 0 | BQ29: 0 | BR29: 0 | BS29: 0 | BT29: 0 | BU29: 0 | BV29: 0 | BW29: 0 | BX29: 0 | BY29: 0 | BZ29: 0 | CA29: 0 | CB29: 0 | CC29: 0 | CD29: -0.875 | CE29: 0 | CF29: 0 | CG29: 0 | CH29: 0 | CI29: 0 | CJ29: 0 | CK29: 0 | CL29: 0 | CM29: 0 | CN29: 0 | CO29: 0 | CP29: 0 | CQ29: 0 | CR29: 0 | CS29: 0 | CT29: 0 | CU29: 0 | CV29: 0 | CW29: 0 | CX29: 0.875 | CY29: 0 | CZ29: 0 | DA29: 0 | DB29: 0 | DC29: 0 | DD29: 0 | DE29: 0 | DF29: 0 | DG29: 0 | DH29: 0 | DI29: -0.875 | DJ29: 0 | DK29: 0 | DL29: 0 | DM29: 0 | DN29: 0 | DO29: 0 | DP29: 0 | DQ29: 0 | DR29: 0 | DS29: 0 | DT29: 0 | DU29: 0 | DV29: 0 | DW29: 0 | DX29: 0 | DY29: 0 | DZ29: 0 | EA29: 0 | EB29: 0 | EC29: 0 | ED29: 0 | EE29: 0 | EF29: 0 | EG29: 0 | EH29: 1.125 | EI29: {=VLOOKUP(A29,'Opponent List'!$A1:$P137,16,FALSE)} -> -0.87634657 | EJ29: 0.24863859
A30: E Michigan | B30: 0 | C30: 0 | D30: 0 | E30: 0 | F30: 0 | G30: 0 | H30: 0 | I30: 0 | J30: 0 | K30: 0 | L30: 0 | M30: 0 | N30: 0 | O30: 0 | P30: 0 | Q30: 0 | R30: -0.875 | S30: 0 | T30: 0 | U30: 0 | V30: 0 | W30: 0 | X30: 0 | Y30: 0 | Z30: 0 | AA30: 0 | AB30: 0 | AC30: 0 | AD30: 0 | AE30: 0 | AF30: 0 | AG30: 0 | AH30: -0.875 | AI30: 0 | AJ30: 0 | AK30: 0 | AL30: 0 | AM30: 0 | AN30: 0 | AO30: 1.125 | AP30: 0 | AQ30: -0.875 | AR30: 0 | AS30: 0 | AT30: 0 | AU30: 0 | AV30: 0 | AW30: 0 | AX30: 0 | AY30: 0 | AZ30: 0 | BA30: 0 | BB30: 0 | BC30: -1.125 | BD30: 0 | BE30: 0 | BF30: 0 | BG30: 0 | BH30: 0 | BI30: 0 | BJ30: 0 | BK30: 0 | BL30: 0 | BM30: 0 | BN30: 0 | BO30: -1.125 | BP30: 0 | BQ30: 0 | BR30: 0 | BS30: 0 | BT30: 0 | BU30: 0 | BV30: 0 | BW30: 0 | BX30: 0 | BY30: 0 | BZ30: 0 | CA30: 0 | CB30: 0 | CC30: 0 | CD30: 0 | CE30: 0.875 | CF30: 0 | CG30: 0 | CH30: 0 | CI30: 0 | CJ30: 0 | CK30: 0 | CL30: 0 | CM30: 0 | CN30: 0 | CO30: 0 | CP30: 0 | CQ30: 0 | CR30: 0 | CS30: 0 | CT30: 0 | CU30: 0 | CV30: 0 | CW30: 0 | CX30: 0 | CY30: 0 | CZ30: 0 | DA30: 0 | DB30: 0 | DC30: 0 | DD30: 0 | DE30: 0 | DF30: 0 | DG30: 0 | DH30: 0 | DI30: 0 | DJ30: 0 | DK30: 0 | DL30: 0 | DM30: 0 | DN30: 0 | DO30: 0 | DP30: 0 | DQ30: 0 | DR30: 0 | DS30: 0 | DT30: 0 | DU30: 0 | DV30: 0 | DW30: 0 | DX30: 0 | DY30: 0 | DZ30: 0 | EA30: 0 | EB30: 0 | EC30: 0 | ED30: 0 | EE30: 0 | EF30: 0 | EG30: 0 | EH30: -2.875 | EI30: {=VLOOKUP(A30,'Opponent List'!$A1:$P137,16,FALSE)} -> 1.0045077 | EJ30: -1.8705117
A31: Florida Atlantic | B31: 0 | C31: 0 | D31: 0 | E31: 0 | F31: 0 | G31: 0 | H31: 0 | I31: 0 | J31: 0 | K31: 0 | L31: 0 | M31: 0 | N31: 0 | O31: 0 | P31: -1.125 | Q31: 0 | R31: -0.875 | S31: 0 | T31: 0 | U31: 0 | V31: 0 | W31: 0 | X31: 0 | Y31: 0 | Z31: 0 | AA31: 0 | AB31: 0 | AC31: 0 | AD31: 0 | AE31: 0 | AF31: 0 | AG31: -0.875 | AH31: 0 | AI31: 0 | AJ31: 0 | AK31: 0 | AL31: 0 | AM31: 0 | AN31: 0 | AO31: 0 | AP31: 0 | AQ31: 0 | AR31: 0 | AS31: 0 | AT31: 0 | AU31: 0 | AV31: -0.875 | AW31: 0 | AX31: 0 | AY31: 0 | AZ31: 0 | BA31: 0 | BB31: 0 | BC31: 0 | BD31: 0 | BE31: 0 | BF31: 0 | BG31: 0 | BH31: 0 | BI31: 0 | BJ31: 0 | BK31: 0 | BL31: 0 | BM31: 0 | BN31: 0 | BO31: 0 | BP31: 0 | BQ31: 0 | BR31: 0 | BS31: 0 | BT31: 0 | BU31: 0 | BV31: 0 | BW31: 0 | BX31: 0 | BY31: 0 | BZ31: 0 | CA31: 0 | CB31: 0 | CC31: 0 | CD31: 0 | CE31: 0 | CF31: 0 | CG31: 0 | CH31: 0 | CI31: 0 | CJ31: 0 | CK31: 0 | CL31: 0 | CM31: 0 | CN31: 0 | CO31: 0 | CP31: 0 | CQ31: 0 | CR31: 0 | CS31: 0.875 | CT31: 0 | CU31: 0 | CV31: 0 | CW31: 1.125 | CX31: 0 | CY31: 0 | CZ31: 0 | DA31: 0 | DB31: 0 | DC31: 0 | DD31: 0 | DE31: 0 | DF31: 0 | DG31: 0 | DH31: 0 | DI31: 0 | DJ31: 0 | DK31: 0 | DL31: 0 | DM31: 0 | DN31: 0 | DO31: 0 | DP31: 0 | DQ31: 0 | DR31: -1.125 | DS31: 0 | DT31: 0 | DU31: 0 | DV31: 0 | DW31: 0 | DX31: 0 | DY31: 0 | DZ31: 0 | EA31: 0 | EB31: 0 | EC31: 0 | ED31: 0 | EE31: 0 | EF31: 0 | EG31: 0 | EH31: -2.875 | EI31: {=VLOOKUP(A31,'Opponent List'!$A1:$P137,16,FALSE)} -> 0.2857716 | EJ31: -2.5891425
A32: Florida Intl | B32: 0 | C32: 0 | D32: 0 | E32: 1.125 | F32: 0 | G32: 0 | H32: 0 | I32: 0 | J32: 0 | K32: 0 | L32: -1.125 | M32: 0 | N32: 0 | O32: 0 | P32: 0 | Q32: 0 | R32: 0 | S32: 0 | T32: 0 | U32: 0 | V32: 0 | W32: 0 | X32: 0 | Y32: 0 | Z32: 0 | AA32: 0 | AB32: 0 | AC32: 0 | AD32: 0 | AE32: 0 | AF32: 0 | AG32: 0 | AH32: 0 | AI32: 0 | AJ32: 0 | AK32: 0 | AL32: 0 | AM32: 0 | AN32: 0 | AO32: 0 | AP32: 0 | AQ32: 0 | AR32: 0 | AS32: 0 | AT32: 0 | AU32: 0 | AV32: 0 | AW32: 0 | AX32: 0 | AY32: 0 | AZ32: 0 | BA32: 0 | BB32: 0 | BC32: 0 | BD32: 0 | BE32: 0 | BF32: 0 | BG32: 0 | BH32: 0 | BI32: 0 | BJ32: 0 | BK32: 0 | BL32: 0 | BM32: 0 | BN32: 0 | BO32: 0 | BP32: 0 | BQ32: 0 | BR32: -1.125 | BS32: 0 | BT32: 0 | BU32: 0 | BV32: -1.125 | BW32: 0 | BX32: 0 | BY32: 0 | BZ32: 0 | CA32: 0 | CB32: -0.875 | CC32: 0 | CD32: 0 | CE32: 0 | CF32: 0 | CG32: 0 | CH32: 0 | CI32: 0 | CJ32: 0 | CK32: 0 | CL32: 0 | CM32: 0 | CN32: 0 | CO32: 0 | CP32: 0 | CQ32: 0 | CR32: 0 | CS32: 0 | CT32: 0 | CU32: 0 | CV32: 0 | CW32: 0 | CX32: 0 | CY32: 0 | CZ32: 0 | DA32: 0 | DB32: 0 | DC32: 0 | DD32: 0 | DE32: -0.875 | DF32: -0.875 | DG32: 0 | DH32: 0 | DI32: 0 | DJ32: 0 | DK32: 0 | DL32: 0 | DM32: 0 | DN32: 0 | DO32: 0 | DP32: 0 | DQ32: 0 | DR32: 0 | DS32: 0 | DT32: 0 | DU32: 0 | DV32: 0 | DW32: 0 | DX32: 0 | DY32: 0 | DZ32: 0 | EA32: 0 | EB32: 0 | EC32: 0 | ED32: 0 | EE32: 0 | EF32: 0 | EG32: 0 | EH32: -4.875 | EI32: {=VLOOKUP(A32,'Opponent List'!$A1:$P137,16,FALSE)} -> 2.1667368 | EJ32: -2.7083101
A33: Florida St | B33: 0 | C33: 0 | D33: 0 | E33: 0 | F33: 0 | G33: 0 | H33: 0 | I33: 0 | J33: 0 | K33: 0 | L33: 0 | M33: 0 | N33: 0 | O33: 0 | P33: 0 | Q33: 0 | R33: 0 | S33: 0 | T33: 0 | U33: 0 | V33: 0 | W33: 0 | X33: 0 | Y33: 0 | Z33: 0 | AA33: 0 | AB33: 0 | AC33: 0 | AD33: 0 | AE33: 0.875 | AF33: 0 | AG33: 0 | AH33: 0 | AI33: 0 | AJ33: 0 | AK33: 0 | AL33: 0 | AM33: 0 | AN33: 0 | AO33: 0 | AP33: -0.875 | AQ33: 0 | AR33: 0 | AS33: 0 | AT33: 0 | AU33: 0 | AV33: 0.875 | AW33: 0 | AX33: 0 | AY33: 0 | AZ33: 0 | BA33: 0 | BB33: 0 | BC33: 1.125 | BD33: 0 | BE33: 0 | BF33: 0 | BG33: 0 | BH33: 0 | BI33: 0 | BJ33: 0 | BK33: 0 | BL33: 0 | BM33: 0 | BN33: 0 | BO33: 0 | BP33: 0 | BQ33: 0 | BR33: 0 | BS33: 0 | BT33: 0 | BU33: 0 | BV33: 0 | BW33: 0 | BX33: 0 | BY33: 0 | BZ33: 1.125 | CA33: 0 | CB33: 0 | CC33: 0 | CD33: 0 | CE33: 0 | CF33: 0 | CG33: 0 | CH33: 0 | CI33: 0 | CJ33: 0 | CK33: 0 | CL33: 0 | CM33: 0 | CN33: 0 | CO33: 0 | CP33: 0 | CQ33: 0 | CR33: 0 | CS33: 0 | CT33: 0 | CU33: 0 | CV33: -0.875 | CW33: 1.125 | CX33: 0 | CY33: 0 | CZ33: 0 | DA33: 0 | DB33: 0 | DC33: 0 | DD33: 0 | DE33: 0 | DF33: 0 | DG33: 0 | DH33: 0 | DI33: 0 | DJ33: 0 | DK33: 0 | DL33: 0 | DM33: 0 | DN33: 0 | DO33: 0 | DP33: 0 | DQ33: 0 | DR33: 0 | DS33: 0 | DT33: 0 | DU33: 0 | DV33: 0 | DW33: 0 | DX33: 0 | DY33: 0 | DZ33: 0 | EA33: 0 | EB33: 0 | EC33: 0 | ED33: 0 | EE33: 0 | EF33: 0 | EG33: 0 | EH33: 3.375 | EI33: {=VLOOKUP(A33,'Opponent List'!$A1:$P137,16,FALSE)} -> 0.19763089 | EJ33: 3.5726018
A34: Florida | B34: 0 | C34: 0 | D34: 0 | E34: 0 | F34: 0 | G34: 0 | H34: 0 | I34: 0 | J34: 0 | K34: 0 | L34: 0 | M34: 0 | N34: 0 | O34: 0 | P34: 0 | Q34: 0 | R34: 1.125 | S34: 0 | T34: 0 | U34: 0 | V34: 0 | W34: 0 | X34: 0 | Y34: 0 | Z34: 0 | AA34: 0 | AB34: 0 | AC34: 0 | AD34: 0.875 | AE34: 0 | AF34: 0 | AG34: 0 | AH34: 0 | AI34: 0 | AJ34: 0 | AK34: 0 | AL34: 0 | AM34: 0 | AN34: 0 | AO34: 0 | AP34: 0 | AQ34: 0 | AR34: 0 | AS34: 0 | AT34: 0 | AU34: 0 | AV34: 0 | AW34: 0 | AX34: 0 | AY34: 0 | AZ34: 0 | BA34: 0 | BB34: 0 | BC34: 0 | BD34: 0 | BE34: 0 | BF34: 0 | BG34: 0 | BH34: 0 | BI34: 0 | BJ34: 0 | BK34: 0 | BL34: 0 | BM34: 0 | BN34: 0 | BO34: 0 | BP34: 0 | BQ34: 0 | BR34: 0 | BS34: 0 | BT34: 0 | BU34: 0 | BV34: 0.875 | BW34: 0 | BX34: 0.875 | BY34: 0 | BZ34: 0 | CA34: 0 | CB34: 0 | CC34: 0 | CD34: 0 | CE34: 0 | CF34: 0 | CG34: 0 | CH34: 1.125 | CI34: 0 | CJ34: 0 | CK34: 0.875 | CL34: 0 | CM34: 0 | CN34: 0 | CO34: 0 | CP34: 0 | CQ34: 0 | CR34: 0 | CS34: 0 | CT34: 0 | CU34: 1.125 | CV34: 0 | CW34: 0 | CX34: 0 | CY34: 0 | CZ34: 0 | DA34: 0 | DB34: 0 | DC34: 0 | DD34: 0 | DE34: 0 | DF34: 0 | DG34: 0 | DH34: 0 | DI34: 0 | DJ34: 0 | DK34: 0 | DL34: 0 | DM34: 0 | DN34: 0 | DO34: 0 | DP34: 0 | DQ34: 0 | DR34: 0 | DS34: 0 | DT34: 0 | DU34: 0 | DV34: 0 | DW34: 0 | DX34: 0 | DY34: 0 | DZ34: 0 | EA34: 0 | EB34: 0 | EC34: 0 | ED34: 0 | EE34: 0 | EF34: 0 | EG34: 0 | EH34: 6.875 | EI34: {=VLOOKUP(A34,'Opponent List'!$A1:$P137,16,FALSE)} -> 0.016794143 | EJ34: 6.8918867
A35: Fresno St | B35: 0 | C35: 0 | D35: 0 | E35: 0 | F35: 0 | G35: 0 | H35: 0 | I35: 0 | J35: 0 | K35: 0 | L35: 0 | M35: 0 | N35: 0 | O35: 0 | P35: 0 | Q35: 0 | R35: 0 | S35: 0 | T35: 0 | U35: 0 | V35: -0.875 | W35: 0 | X35: 0 | Y35: 0 | Z35: 0 | AA35: 0 | AB35: 0 | AC35: 0 | AD35: 0 | AE35: 0 | AF35: 0 | AG35: 0 | AH35: 0 | AI35: 0 | AJ35: 0 | AK35: 0 | AL35: 0 | AM35: 0 | AN35: 0 | AO35: 0 | AP35: 0 | AQ35: 0 | AR35: 0 | AS35: 0 | AT35: 0 | AU35: 0 | AV35: 0 | AW35: 0 | AX35: 0 | AY35: 0 | AZ35: 0 | BA35: 0 | BB35: 0 | BC35: 0 | BD35: 0 | BE35: -0.875 | BF35: 0 | BG35: 0 | BH35: 0 | BI35: 0 | BJ35: 0 | BK35: 0 | BL35: 0 | BM35: 0 | BN35: 0 | BO35: 0 | BP35: 0 | BQ35: 0 | BR35: 0 | BS35: 0 | BT35: 0 | BU35: -1.125 | BV35: 0 | BW35: 0 | BX35: 0 | BY35: 0 | BZ35: 0 | CA35: 0 | CB35: 1.125 | CC35: 0 | CD35: 0 | CE35: 0 | CF35: -1.125 | CG35: 0 | CH35: 0 | CI35: 0 | CJ35: 0 | CK35: 0 | CL35: 0 | CM35: 0 | CN35: 1.125 | CO35: 0 | CP35: 0 | CQ35: 0 | CR35: 0 | CS35: 0 | CT35: 0 | CU35: 0 | CV35: 0 | CW35: 0 | CX35: 0 | CY35: 0 | CZ35: 0 | DA35: 0 | DB35: 0 | DC35: 0 | DD35: 0 | DE35: 0 | DF35: 0 | DG35: 0 | DH35: 0 | DI35: 0 | DJ35: 0 | DK35: 0 | DL35: 0 | DM35: -0.875 | DN35: 0 | DO35: 0 | DP35: 0 | DQ35: 0 | DR35: 0 | DS35: 0 | DT35: 0 | DU35: 0 | DV35: 0 | DW35: 0 | DX35: 0 | DY35: 0 | DZ35: 0 | EA35: 0 | EB35: 0 | EC35: 0 | ED35: 0 | EE35: 0 | EF35: 0 | EG35: 0 | EH35: -2.625 | EI35: {=VLOOKUP(A35,'Opponent List'!$A1:$P137,16,FALSE)} -> -0.61706952 | EJ35: -3.2421483
A36: Georgia So | B36: 0 | C36: 0 | D36: 0 | E36: 0 | F36: 0 | G36: 0 | H36: 0 | I36: 0 | J36: 0 | K36: 0 | L36: 0 | M36: 0 | N36: 0 | O36: 0 | P36: 0 | Q36: 0 | R36: 0 | S36: -0.875 | T36: 0 | U36: 0 | V36: 0 | W36: 0 | X36: 0 | Y36: 0 | Z36: 0 | AA36: 0 | AB36: 0 | AC36: 0 | AD36: 0 | AE36: 0 | AF36: 0 | AG36: 0 | AH36: 0 | AI36: 0 | AJ36: 0 | AK36: 0 | AL36: 0 | AM36: 0 | AN36: 0 | AO36: 0 | AP36: 0 | AQ36: 0 | AR36: 0 | AS36: 0 | AT36: 0 | AU36: 0 | AV36: 0 | AW36: 0.875 | AX36: 0 | AY36: 0 | AZ36: 0 | BA36: 0 | BB36: 0 | BC36: 0 | BD36: 0 | BE36: 0 | BF36: 0 | BG36: 0 | BH36: -0.875 | BI36: 0 | BJ36: 0 | BK36: 0 | BL36: 0 | BM36: 0 | BN36: 0 | BO36: 0 | BP36: 0 | BQ36: 0 | BR36: 0 | BS36: 0 | BT36: 0 | BU36: 0 | BV36: 0 | BW36: 0 | BX36: 0 | BY36: 0 | BZ36: 0 | CA36: 0 | CB36: 0 | CC36: -0.875 | CD36: 0 | CE36: 0 | CF36: 0 | CG36: 0 | CH36: 0 | CI36: 0 | CJ36: 0 | CK36: 0 | CL36: 0 | CM36: 0 | CN36: 0.875 | CO36: 0 | CP36: 0 | CQ36: 0 | CR36: 0 | CS36: 0 | CT36: 0 | CU36: 0 | CV36: 0 | CW36: 0 | CX36: 0 | CY36: 0 | CZ36: 0 | DA36: 0 | DB36: 0 | DC36: 0 | DD36: 0 | DE36: 0 | DF36: -1.125 | DG36: 0 | DH36: 0 | DI36: 0 | DJ36: 0 | DK36: 0 | DL36: 0 | DM36: 0 | DN36: 0 | DO36: 0 | DP36: 0 | DQ36: 0 | DR36: -0.875 | DS36: 0 | DT36: 0 | DU36: 0 | DV36: 0 | DW36: 0 | DX36: 0 | DY36: 0 | DZ36: 0 | EA36: 0 | EB36: 0 | EC36: 0 | ED36: 0 | EE36: 0 | EF36: 0 | EG36: 0 | EH36: -2.875 | EI36: {=VLOOKUP(A36,'Opponent List'!$A1:$P137,16,FALSE)} -> 2.3368106 | EJ36: -0.53831982
A37: Georgia St | B37: 0 | C37: 0 | D37: 0 | E37: 0 | F37: 0 | G37: 0 | H37: 0 | I37: 0 | J37: 0 | K37: 0 | L37: -0.875 | M37: 0 | N37: 0 | O37: 0 | P37: 0 | Q37: 0 | R37: 0 | S37: -1.125 | T37: 0 | U37: 0 | V37: 0 | W37: 0 | X37: 0 | Y37: 0 | Z37: 0 | AA37: 0 | AB37: 0 | AC37: 0 | AD37: 0 | AE37: 0 | AF37: 0 | AG37: 0 | AH37: 0 | AI37: 0 | AJ37: 0 | AK37: 0 | AL37: 0 | AM37: 0 | AN37: 0 | AO37: 0 | AP37: 0 | AQ37: 0 | AR37: 0 | AS37: 0 | AT37: 0 | AU37: 0 | AV37: 0 | AW37: 0 | AX37: 0 | AY37: 0 | AZ37: 0 | BA37: 0 | BB37: 0 | BC37: 0 | BD37: 0 | BE37: 0 | BF37: 0 | BG37: 0 | BH37: 0 | BI37: 0 | BJ37: 0 | BK37: 0 | BL37: 0 | BM37: 0 | BN37: 0 | BO37: 0 | BP37: 0 | BQ37: 0 | BR37: 0 | BS37: 0 | BT37: 0 | BU37: 0 | BV37: 0 | BW37: -0.875 | BX37: 0 | BY37: 0 | BZ37: 0 | CA37: 0 | CB37: 0 | CC37: 0 | CD37: 0 | CE37: 0 | CF37: 0 | CG37: 0 | CH37: 0 | CI37: 0 | CJ37: 0 | CK37: 0 | CL37: 0 | CM37: 0 | CN37: 0 | CO37: 0 | CP37: -0.25 | CQ37: 0 | CR37: 0 | CS37: 0 | CT37: 0 | CU37: 0 | CV37: 0 | CW37: 0 | CX37: -0.875 | CY37: 0 | CZ37: -1.125 | DA37: 0 | DB37: 0 | DC37: 0 | DD37: 0 | DE37: 0 | DF37: 0 | DG37: 0 | DH37: 0 | DI37: 0 | DJ37: 0 | DK37: 0 | DL37: 0 | DM37: 0 | DN37: 0 | DO37: 0 | DP37: 0 | DQ37: 0 | DR37: 0 | DS37: 0 | DT37: 0 | DU37: 0 | DV37: 0 | DW37: 0 | DX37: 0 | DY37: 0 | DZ37: 0 | EA37: 0 | EB37: 0 | EC37: 0 | ED37: 0 | EE37: 0 | EF37: 0 | EG37: 0 | EH37: -5.125 | EI37: {=VLOOKUP(A37,'Opponent List'!$A1:$P137,16,FALSE)} -> -0.43359088 | EJ37: -5.5585763
